Workbook

Sheet Term-1
B1: May2023 - Sept2023 | G1: Seed Date | H1: 45076 | J1: Profit | K1: =M2-E2 -> -790524
D2: Total : | E2: =SUM(E5:E30) -> 2050924 | G2: Days | H2: 75 days | L2: Total : | M2: =SUM(M5:M30) -> 1260400
B3: Investment | G3: Growth | J3: Income
B4: # | C4: Date | D4: Item | E4: Amount | F4: Details | G4: Date | H4: Count | J4: # | K4: Date | L4: Item | M4: Amount | N4: Details
B5: 1 | C5: 45025 | D5: Bhoomi Magatha | E5: 200000 | F5: 5x80K | G5: 45126 | H5: 120 | I5: =IF(ISBLANK(G5),"",CONCATENATE(G5-$H$1+1," days")) -> 51 days | J5: 1 | K5: 45150 | L5: Pedda Cheruvu - 4000 | M5: 940000 | N5: 4K, 80 count, 225 price
B6: 2 | C6: 45027 | D6: JCB and Labor | E6: 21401 | G6: 45133 | H6: 108 | I6: =IF(ISBLANK(G6),"",CONCATENATE(G6-$H$1+1," days")) -> 58 days | J6: 2 | K6: 45173 | L6: Chinna Cheruvu - 1.2 | M6: 320400 | N6: 1285kg
B7: 3 | C7: 45029 | D7: SubMercible Motors | E7: 64000 | F7: 2 motors | G7: 45140 | H7: 92 | I7: =IF(ISBLANK(G7),"",CONCATENATE(G7-$H$1+1," days")) -> 65 days | J7: 3
B8: 4 | C8: 45029 | D8: Bore | E8: 30400 | G8: 45150 | H8: 80 | I8: =IF(ISBLANK(G8),"",CONCATENATE(G8-$H$1+1," days")) -> 75 days | J8: 4
B9: 5 | C9: 45029 | D9: MonoBlock Motors | E9: 47000 | F9: 2 motors and Kirayi | J9: 5
B10: 6 | C10: 45029 | D10: Saman from Korukollu | E10: 17302 | J10: 6
B11: 7 | C11: 45056 | D11: Change Over Board Saman | E11: 23500 | F11: Electric saman & Plywood from Nouduru | J11: 7
B12: 8 | C12: 45062 | D12: Leggalu Work | E12: 12700 | G12: Chinna Cheruvu | J12: 8
B13: 9 | C13: 45065 | D13: New Fan Sets (6) | E13: 198000 | F13: 6x33000 | G13: Seed Date | H13: 45114 | J13: 9
B14: 10 | C14: 45065 | D14: Electric Items | E14: 58980 | G14: Days | H14: 59 Days | J14: 10
B15: 11 | C15: 45074 | D15: Seed | E15: 150000 | F15: 5 Lakhs | G15: Growth | J15: 11
B16: 12 | C16: 45074 | D16: Kirayi | E16: 9000 | F16: Kirayi+Beta | G16: Date | H16: Count | J16: 12
B17: 13 | C17: 45061 | D17: Boat, Shed, Wire,Fans | E17: 120000 | F17: Old wire, Old Fans (4) | G17: 45163 | H17: 115 | I17: =IF(ISBLANK(G17),"",CONCATENATE(G17-$H$13+1," days")) -> 50 days | J17: 13
B18: 14 | C18: 45090 | D18: meta Bastalu - 20 | E18: 43050 | F18: 20x2140 + 50 + 200 | G18: 45169 | H18: 105 | I18: =IF(ISBLANK(G18),"",CONCATENATE(G18-$H$13+1," days")) -> 56 days | J18: 14
B19: 15 | C19: 45093 | D19: Current Bill | E19: 24768 | F19: To BVRM Gpay-AAO/ERO/APEPDCL | G19: 45171 | H19: 100 | I19: =IF(ISBLANK(G19),"",CONCATENATE(G19-$H$13+1," days")) -> 58 days | J19: 15
B20: 16 | C20: 45100 | D20: Metha Bastalu - 20 | E20: 42650 | F20: 20x2140 | G20: 45173 | H20: 87 | I20: =IF(ISBLANK(G20),"",CONCATENATE(G20-$H$13+1," days")) -> 60 days | J20: 16
B21: 17 | C21: 45105 | D21: New Fan Sets (3) | E21: 120000 | F21: 3*32000 | J21: 17
B22: 18 | C22: 45123 | D22: Current Bill | E22: 25193 | F22: Gpay from Venky Mobile | I22: =IF(ISBLANK(G22),"",CONCATENATE("(",G22-$H$13+1," days)")) | J22: 18
B23: 19 | C23: 45150 | D23: Cheruvu Pattina Karchu | E23: 20000 | J23: 19
B24: 20 | C24: 45150 | D24: Medicine | E24: 140000 | J24: 20
B25: 21 | C25: 45150 | D25: Assam Boy Salary | E25: 30000 | F25: 2x15000 | J25: 21
B26: 22 | C26: 45150 | D26: Total Metha Karchu ( Aruvu) | E26: 600000 | J26: 22
B27: 23 | C27: 45154 | D27: Others | E27: 52980 | J27: 23
B28: 24 | J28: 24
B29: 25 | J29: 25
B30: 26 | J30: 26
E31: Total Seed: | F31: 700000 | G31: Big Tank: | H31: 600000 | I31: Small Tank: | J31: 10000
E32: Trip | F32: Number | G32: Count | H32: Quantity | I32: Price | J32: Total
E33: Big Tank | F33: =H33*G33 -> 320000 | G33: 80 | H33: 4000 | I33: 235 | J33: =H33*I33 -> 940000
E34: Small Tank | F34: =H34*G34 -> 104400 | G34: 87 | H34: 1200 | I34: 267 | J34: =H34*I34 -> 320400
F35: =H35*G35 -> 0 | J35: =H35*I35 -> 0
F36: =H36*G36 -> 0 | J36: =H36*I36 -> 0
F37: =H37*G37 -> 0 | J37: =H37*I37 -> 0
F38: =H38*G38 -> 0 | J38: =H38*I38 -> 0
F39: =H39*G39 -> 0 | J39: =H39*I39 -> 0
E40: Total: | F40: =SUM(F33:F38) -> 424400 | H40: =SUM(H33:H39) -> 5200 | J40: =SUM(J33:J39) -> 1260400
...

Sheet Term-2
B1: Sept2023 - Nov2023 | G1: Seed Date | H1: 45163 | J1: Profit | K1: =M2-E2 -> -218110
D2: Total : | E2: =SUM(E5:E30) -> 518110 | G2: Days | H2: 27 days | L2: Total : | M2: =SUM(M5:M30) -> 300000
B3: Investment | G3: Growth | J3: Income
B4: # | C4: Date | D4: Item | E4: Amount | F4: Details | G4: Date | H4: Count | J4: # | K4: Date | L4: Item | M4: Amount | N4: Details
B5: 1 | C5: 45163 | D5: Seed | E5: 180000 | F5: 6Lx0.30 | G5: 45189 | H5: 325 | I5: =IF(ISBLANK(G5),"",CONCATENATE(G5-$H$1+1," days")) -> 27 days | J5: 1 | K5: 45189 | L5: Total | M5: 300000
B6: 2 | C6: 45163 | D6: Seed Kirayi | E6: 10000 | I6: =IF(ISBLANK(G6),"",CONCATENATE("(",G6-$H$1+1," days)")) | J6: 2
B7: 3 | C7: 45167 | D7: Metha | I7: =IF(ISBLANK(G7),"",CONCATENATE("(",G7-$H$1+1," days)")) | J7: 3
B8: 4 | C8: 45181 | D8: CurrentBill | E8: 28110 | I8: =IF(ISBLANK(G8),"",CONCATENATE("(",G8-$H$1+1," days)")) | J8: 4
B9: 5 | D9: Feed | E9: 300000 | I9: =IF(ISBLANK(G9),"",CONCATENATE("(",G9-$H$1+1," days)")) | J9: 5
B10: 6 | I10: =IF(ISBLANK(G10),"",CONCATENATE("(",G10-$H$1+1," days)")) | J10: 6
B11: 7 | J11: 7
B12: 8 | G12: Chinna Cheruvu | J12: 8
B13: 9 | G13: Seed Date | H13: 45163 | J13: 9
B14: 10 | G14: Days | H14: 27 days | J14: 10
B15: 11 | G15: Growth | J15: 11
B16: 12 | G16: Date | H16: Count | J16: 12
B17: 13 | G17: 45189 | H17: 325 | I17: =IF(ISBLANK(G17),"",CONCATENATE(G17-$H$13+1," days")) -> 27 days | J17: 13
B18: 14 | I18: =IF(ISBLANK(G18),"",CONCATENATE("(",G18-$H$13+1," days)")) | J18: 14
B19: 15 | I19: =IF(ISBLANK(G19),"",CONCATENATE("(",G19-$H$13+1," days)")) | J19: 15
B20: 16 | I20: =IF(ISBLANK(G20),"",CONCATENATE("(",G20-$H$13+1," days)")) | J20: 16
B21: 17 | I21: =IF(ISBLANK(G21),"",CONCATENATE("(",G21-$H$13+1," days)")) | J21: 17
B22: 18 | J22: 18
B23: 19 | J23: 19
B24: 20 | J24: 20
B25: 21 | J25: 21
B26: 22 | J26: 22
B27: 23 | J27: 23
B28: 24 | J28: 24
B29: 25 | J29: 25
J30: 26
E31: Total Seed: | F31: 800000 | G31: Big Tank: | H31: 700000 | I31: Small Tank: | J31: 100000
E32: Trip | F32: Number | G32: Count | H32: Quantity | I32: Price | J32: Total
E33: Big Tank | F33: =H33*G33 -> 620000 | G33: 124 | H33: 5000 | I33: 60 | J33: =H33*I33 -> 300000
J34: =H34*I34 -> 0
J35: =H35*I35 -> 0
J36: =H36*I36 -> 0
J37: =H37*I37 -> 0
J38: =H38*I38 -> 0
J39: =H39*I39 -> 0
E40: Total: | F40: =SUM(F33:F38) -> 620000 | H40: =SUM(H33:H39) -> 5000 | J40: =SUM(J33:J39) -> 300000
...

Sheet Term-3
B1: Nov2023 - Jan2024 | G1: Seed Date | H1: 45163 | J1: Profit | K1: =M2-E2 -> -470000
D2: Total : | E2: =SUM(E5:E30) -> 590000 | G2: Days | H2: 37 days | L2: Total : | M2: =SUM(M5:M30) -> 120000
B3: Investment | G3: Growth | J3: Income
B4: # | C4: Date | D4: Item | E4: Amount | F4: Details | G4: Date | H4: Count | J4: # | K4: Date | L4: Item | M4: Amount | N4: Details
B5: 1 | C5: 45163 | D5: Seed | E5: 180000 | F5: 6Lx0.30 | G5: 45199 | H5: 325 | I5: =IF(ISBLANK(G5),"",CONCATENATE(G5-$H$1+1," days")) -> 37 days | J5: 1 | K5: 45189 | L5: total | M5: 120000
B6: 2 | C6: 45163 | D6: Seed Kirayi | E6: 10000 | I6: =IF(ISBLANK(G6),"",CONCATENATE("(",G6-$H$1+1," days)")) | J6: 2
B7: 3 | C7: 45167 | D7: Metha | E7: 300000 | I7: =IF(ISBLANK(G7),"",CONCATENATE("(",G7-$H$1+1," days)")) | J7: 3
B8: 4 | D8: Others | E8: 100000 | I8: =IF(ISBLANK(G8),"",CONCATENATE("(",G8-$H$1+1," days)")) | J8: 4
B9: 5 | I9: =IF(ISBLANK(G9),"",CONCATENATE("(",G9-$H$1+1," days)")) | J9: 5
B10: 6 | I10: =IF(ISBLANK(G10),"",CONCATENATE("(",G10-$H$1+1," days)")) | J10: 6
B11: 7 | J11: 7
B12: 8 | G12: Chinna Cheruvu | J12: 8
B13: 9 | G13: Seed Date | H13: 45163 | J13: 9
B14: 10 | G14: Days | H14: 37 days | J14: 10
B15: 11 | G15: Growth | J15: 11
B16: 12 | G16: Date | H16: Count | J16: 12
B17: 13 | G17: 45199 | H17: 325 | I17: =IF(ISBLANK(G17),"",CONCATENATE(G17-$H$13+1," days")) -> 37 days | J17: 13
B18: 14 | I18: =IF(ISBLANK(G18),"",CONCATENATE("(",G18-$H$13+1," days)")) | J18: 14
B19: 15 | I19: =IF(ISBLANK(G19),"",CONCATENATE("(",G19-$H$13+1," days)")) | J19: 15
B20: 16 | I20: =IF(ISBLANK(G20),"",CONCATENATE("(",G20-$H$13+1," days)")) | J20: 16
B21: 17 | I21: =IF(ISBLANK(G21),"",CONCATENATE("(",G21-$H$13+1," days)")) | J21: 17
B22: 18 | J22: 18
B23: 19 | J23: 19
B24: 20 | J24: 20
B25: 21 | J25: 21
B26: 22 | J26: 22
B27: 23 | J27: 23
B28: 24 | J28: 24
B29: 25 | J29: 25
J30: 26
E31: Total Seed: | F31: 700000 | G31: Big Tank: | H31: 900000 | I31: Small Tank: | J31: 100000
E32: Trip | F32: Number | G32: Count | H32: Quantity | I32: Price | J32: Total
E33: Big Tank | F33: =H33*G33 -> 325000 | G33: 325 | H33: 1000 | I33: 100 | J33: =H33*I33 -> 100000
E34: Small Tank | F34: =H34*G34 -> 65000 | G34: 325 | H34: 200 | I34: 100 | J34: =H34*I34 -> 20000
F35: =H35*G35 -> 0 | J35: =H35*I35 -> 0
F36: =H36*G36 -> 0 | J36: =H36*I36 -> 0
F37: =H37*G37 -> 0 | J37: =H37*I37 -> 0
F38: =H38*G38 -> 0 | J38: =H38*I38 -> 0
F39: =H39*G39 -> 0 | J39: =H39*I39 -> 0
E40: Total: | F40: =SUM(F33:F38) -> 390000 | H40: =SUM(H33:H39) -> 1200 | J40: =SUM(J33:J39) -> 120000
...

Sheet Term-4
B1: Feb2024 - May2024 | G1: Seed Date | H1: 45345 | J1: Profit | K1: =M2-E2 -> 1098545
D2: Total : | E2: =SUM(E5:E30) -> 1601499 | G2: Days | H2: 72 days | L2: Total : | M2: =SUM(M5:M22) -> 2700044
B3: Investment | G3: Growth | J3: Income
B4: # | C4: Date | D4: Item | E4: Amount | F4: Details | G4: Date | H4: Count | J4: # | K4: Date | L4: Item | M4: Amount | N4: Details
B5: 1 | C5: 45344 | G5: 45396 | H5: 124 | I5: =IF(ISBLANK(G5),"",CONCATENATE(G5-$H$1+1," days")) -> 52 days | J5: 1 | K5: 45399 | L5: 1st Middle: Tones-200 Count-107 | M5: 432360
B6: 2 | D6: Feed | E6: 1015118 | G6: 45399 | H6: 107 | I6: =IF(ISBLANK(G6),"",CONCATENATE(G6-$H$1+1," days")) -> 55 days | J6: 2 | K6: 45408 | L6: 2nd Middle: Tones-230 Count-80 | M6: 454020
B7: 3 | D7: Seed & Others | E7: 436381 | F7: From Vizianagaram | G7: 45404 | H7: 88 | I7: =IF(ISBLANK(G7),"",CONCATENATE(G7-$H$1+1," days")) -> 60 days | J7: 3 | K7: 45408 | L7: Chinna Tank-937T-270 Count-60 | M7: 253179
B8: 4 | D8: Feed-30 bags | E8: 65000 | G8: 45407 | H8: 80 | I8: =IF(ISBLANK(G8),"",CONCATENATE(G8-$H$1+1," days")) -> 63 days | J8: 4 | K8: 45416 | L8: 3rd Middle: 2164 tones -250 Count-70 | M8: 535000
B9: 5 | D9: Feed | E9: 85000 | G9: 45408 | H9: 78 | I9: =IF(ISBLANK(G9),"",CONCATENATE(G9-$H$1+1," days")) -> 64 days | J9: 5 | K9: 45421 | L9: Final-3740 tones-275 count 60 | M9: 1025485
B10: 6 | G10: 45415 | H10: 62 | I10: =IF(ISBLANK(G10),"",CONCATENATE(G10-$H$1+1," days")) -> 71 days | J10: 6
B11: 7 | G11: 45416 | H11: 65 | I11: =IF(ISBLANK(G11),"",CONCATENATE(G11-$H$1+1," days")) -> 72 days | J11: 7
B12: 8 | G12: 45419 | H12: 58 | I12: =IF(ISBLANK(G12),"",CONCATENATE(G12-$H$1+1," days")) -> 75 days | J12: 8
B13: 9 | G13: 45421 | H13: 58 | I13: =IF(ISBLANK(G13),"",CONCATENATE(G13-$H$1+1," days")) -> 77 days | J13: 9
B14: 10 | G14: Small Tank Seed Date | J14: 10
B15: 11 | G15: Seed Date | H15: 45345 | J15: 11
B16: 12 | G16: Days | H16: 72 days | J16: 12
B17: 13 | G17: Growth | J17: 13
B18: 14 | G18: Date | H18: Count | J18: 14
B19: 15 | G19: 45404 | H19: 60 | I19: =IF(ISBLANK(G19),"",CONCATENATE(G19-$H$15+1," days")) -> 60 days | J19: 15
B20: 16 | G20: 45408 | H20: 57 | I20: =IF(ISBLANK(G20),"",CONCATENATE(G20-$H$15+1," days")) -> 64 days | J20: 16
B21: 17 | I21: =IF(ISBLANK(G21),"",CONCATENATE("(",G21-$H$15+1," days)")) | J21: 17
B22: 18 | I22: =IF(ISBLANK(G22),"",CONCATENATE("(",G22-$H$15+1," days)")) | J22: 18
B23: 19
B24: 20
B25: 21
B26: 22
B27: 23
B28: 24
B29: 25
E31: Total Seed: | F31: 700000 | G31: Big Tank: | H31: 900000 | I31: Small Tank: | J31: 150000
E32: Trip | F32: Number | G32: Count | H32: Quantity | I32: Price | J32: Total
E33: 1st Middle- Function | F33: =H33*G33 -> 210148 | G33: 107 | H33: 1964 | I33: 220 | J33: =H33*I33 -> 432080
E34: 2nd Middle | F34: =H34*G34 -> 165200 | G34: 80 | H34: 2065 | I34: 220 | J34: =H34*I34 -> 454300
E35: Small Tank | F35: =H35*G35 -> 56640 | G35: 60 | H35: 944 | I35: 270 | J35: =H35*I35 -> 254880
E36: 3rd Middle | F36: =H36*G36 -> 151480 | G36: 70 | H36: 2164 | I36: 250 | J36: =H36*I36 -> 541000
E37: Final | F37: =H37*G37 -> 224400 | G37: 60 | H37: 3740 | I37: 270 | J37: =H37*I37 -> 1009800
J38: =H38*I38 -> 0
F39: =H39*G39 -> 0 | J39: =H39*I39 -> 0
E40: Total: | F40: =SUM(F33:F38) -> 807868 | H40: =SUM(H33:H39) -> 10877 | J40: =SUM(J33:J39) -> 2692060
E41: Number Found | F41: =CONCATENATE(ROUND((F40/F31)*100,2),"%") -> 115.41% | M41: =SUM(M33:M40) -> 0
...

Sheet Term-5
B1: July 2024 - Sept2024 | G1: Seed Date | H1: 45477 | J1: Profit | K1: =M2-E2 -> 391120
D2: Total : | E2: =SUM(E5:E30) -> 1221202 | G2: Days | H2: 58 days | L2: Total : | M2: =SUM(M5:M22) -> 1612322
B3: Investment | G3: Growth | J3: Income
B4: # | C4: Date | D4: Item | E4: Amount | F4: Details | G4: Date | H4: Count | J4: # | K4: Date | L4: Item | M4: Amount | N4: Details
B5: 1 | C5: 45446 | D5: Cheruvu Pani | E5: 40000 | G5: 45527 | H5: 110 | I5: =IF(ISBLANK(G5),"",CONCATENATE(G5-$H$1+1," days")) -> 51 days | J5: 1 | K5: 45534 | L5: Big Tank-5389.8 kgs-249 rate - count 111 | M5: 1334590
B6: 2 | C6: 45477 | D6: Seed | E6: 262500 | F6: 1200*800 | G6: 45534 | H6: 111 | I6: =IF(ISBLANK(G6),"",CONCATENATE(G6-$H$1+1," days")) -> 58 days | J6: 2 | K6: 45543 | L6: Small Tank-1068 kg-260 rate-92 count | M6: 277732
B7: 3 | C7: 45477 | D7: Van Kirayi | E7: 12000 | I7: =IF(ISBLANK(G7),"",CONCATENATE("(",G7-$H$1+1," days)")) | J7: 3
B8: 4 | C8: 45474 | D8: Others | E8: 30000 | I8: =IF(ISBLANK(G8),"",CONCATENATE("(",G8-$H$1+1," days)")) | J8: 4
B9: 5 | C9: 45537 | D9: Mogallu Feed Shop | E9: 623857 | F9: Feed + Medicine | I9: =IF(ISBLANK(G9),"",CONCATENATE("(",G9-$H$1+1," days)")) | J9: 5
B10: 6 | C10: 45550 | D10: Aravalli Shop | E10: 133202 | I10: =IF(ISBLANK(G10),"",CONCATENATE("(",G10-$H$1+1," days)")) | J10: 6
B11: 7 | C11: 45534 | D11: Current Bill, Assam Salary etc | E11: 100000 | I11: =IF(ISBLANK(G11),"",CONCATENATE("(",G11-$H$1+1," days)")) | J11: 7
B12: 8 | C12: 45550 | D12: Mogallu Feed Shop-Extra | E12: 19643 | I12: =IF(ISBLANK(G12),"",CONCATENATE("(",G12-$H$1+1," days)")) | J12: 8
B13: 9 | D13: Surya Calculation: | I13: =IF(ISBLANK(G13),"",CONCATENATE("(",G13-$H$1+1," days)")) | J13: 9
B14: 10 | G14: Small Tank Seed Date | J14: 10
B15: 11 | G15: Seed Date | H15: 45477 | J15: 11
B16: 12 | G16: Days | H16: 67 days | J16: 12
B17: 13 | G17: Growth | J17: 13
B18: 14 | G18: Date | H18: Count | J18: 14
B19: 15 | G19: 45527 | H19: 106 | I19: =IF(ISBLANK(G19),"",CONCATENATE(G19-$H$15+1," days")) -> 51 days | J19: 15
B20: 16 | G20: 45534 | H20: 96 | I20: =IF(ISBLANK(G20),"",CONCATENATE(G20-$H$15+1," days")) -> 58 days | J20: 16
B21: 17 | G21: 45541 | H21: 91 | I21: =IF(ISBLANK(G21),"",CONCATENATE(G21-$H$15+1," days")) -> 65 days | J21: 17
B22: 18 | G22: 45543 | H22: 92 | I22: =IF(ISBLANK(G22),"",CONCATENATE(G22-$H$15+1," days")) -> 67 days | J22: 18
B23: 19 | J23: 19
B24: 20 | J24: 20
B25: 21 | J25: 21
B26: 22 | J26: 22
B27: 23 | J27: 23
B28: 24 | J28: 24
B29: 25 | J29: 25
E31: Total Seed: | F31: 750000 | G31: Big Tank: | H31: 900000 | I31: Small Tank: | J31: 150000
E32: Trip | F32: Number | G32: Count | H32: Quantity | I32: Price | J32: Total | L32: Cash Credits
E33: Big Tank - Full | F33: =H33*G33 -> 591607.8 | G33: 111 | H33: 5329.8 | I33: 249 | J33: =H33*I33 -> 1327120.2 | L33: Feed Shop | M33: 600000
E34: Big Tank - Soft | F34: =H34*G34 -> 6660 | G34: 111 | H34: 60 | I34: 124.5 | J34: =H34*I34 -> 7470 | L34: Surya | M34: 250000
E35: Small Tank - Full | F35: =H35*G35 -> 98274.4 | G35: 92 | H35: 1068.2 | I35: 250 | J35: =H35*I35 -> 267050 | L35: Surya | M35: 50000
F36: =H36*G36 -> 0 | H36: 1068.2 | I36: 10 | J36: =H36*I36 -> 10682 | L36: Cash | M36: 568000
F37: =H37*G37 -> 0 | J37: =H37*I37 -> 0 | L37: Feed Shop Manchili (-) | M37: 133202
F38: =H38*G38 -> 0 | J38: =H38*I38 -> 0 | L38: Cash | M38: 10000
F39: =H39*G39 -> 0 | J39: =H39*I39 -> 0
E40: Total: | F40: =SUM(F33:F38) -> 696542.2 | H40: =SUM(H33:H39) -> 7526.2 | J40: =SUM(J33:J39) -> 1612322.2
E41: Number Found | F41: =CONCATENATE(ROUND((F40/F31)*100,2),"%") -> 92.87% | L41: Total: | M41: =SUM(M33:M40) -> 1611202
...

Sheet Term-6
B1: Sep2024 - Nov2024 | G1: Seed Date | H1: 45548 | J1: Profit | K1: =M2-E2 -> 1002304
D2: Total : | E2: =SUM(E5:E30) -> 1412799 | G2: Days | H2: 73 days | L2: Total : | M2: =SUM(M5:M22) -> 2415103
B3: Investment | G3: Growth | J3: Income
B4: # | C4: Date | D4: Item | E4: Amount | F4: Details | G4: Date | H4: Count | I4: Days | J4: # | K4: Date | L4: Item | M4: Amount | N4: Details
B5: 1 | C5: 45548 | D5: Seed | E5: 210000 | F5: Seed from Anjaneya, Gudur | G5: 45599 | H5: 96 | I5: =IF(ISBLANK(G5),"",CONCATENATE(G5-$H$1+1," days")) -> 52 days | J5: 1 | K5: 45609 | L5: 1st Middle: Tones-2 Rate-270 Count-80 | M5: 558927
B6: 2 | C6: 45548 | D6: Van Kirayi | E6: 30000 | G6: 45602 | H6: 91 | I6: =IF(ISBLANK(G6),"",CONCATENATE(G6-$H$1+1," days")) -> 55 days | J6: 2 | K6: 45620 | L6: Big Tank Final: Tones-4619.9 Rate-320 Count-70 | M6: 1478368
B7: 3 | C7: 45561 | D7: Small Tank Seed | E7: 35000 | F7: Seed from Anjaneya, Gudur | G7: 45606 | H7: 84 | I7: =IF(ISBLANK(G7),"",CONCATENATE(G7-$H$1+1," days")) -> 59 days | J7: 3 | K7: 45633 | L7: Small Tank:Tons-1111.2,Rate-340 count-60 | M7: 377808
B8: 4 | C8: 45561 | D8: Small Tank Seed Kirayi | E8: 3500 | G8: 45608 | H8: 81 | I8: =IF(ISBLANK(G8),"",CONCATENATE(G8-$H$1+1," days")) -> 61 days | J8: 4
B9: 5 | C9: 45520 | D9: Current Bill | E9: 22303 | G9: 45609 | H9: 79 | I9: =IF(ISBLANK(G9),"",CONCATENATE(G9-$H$1+1," days")) -> 62 days | J9: 5
B10: 6 | C10: 45551 | D10: Current Bill | E10: 17625 | G10: 45614 | H10: 65 | I10: =IF(ISBLANK(G10),"",CONCATENATE(G10-$H$1+1," days")) -> 67 days | J10: 6
B11: 7 | C11: 45599 | D11: Danayya Vala | E11: 1200 | G11: 45619 | H11: 70 | I11: =IF(ISBLANK(G11),"",CONCATENATE(G11-$H$1+1," days")) -> 72 days | J11: 7
B12: 8 | C12: 45609 | D12: 1st middle vala payment | E12: 5600 | G12: 45620 | H12: 65 | I12: =IF(ISBLANK(G12),"",CONCATENATE(G12-$H$1+1," days")) -> 73 days | J12: 8
B13: 9 | C13: 45620 | D13: 10 tons feed so far | E13: 893146 | I13: =IF(ISBLANK(G13),"",CONCATENATE(G13-$H$1+1," days")) | J13: 9
B14: 10 | C14: 45620 | D14: Big Tank Vala payment | E14: 17400 | G14: Small Tank | J14: 10
B15: 11 | C15: 45581 | D15: Current Bill | E15: 22755 | G15: Seed Date | H15: 45561 | J15: 11
B16: 12 | C16: 45634 | D16: Small Tank Feed | E16: 27000 | G16: Days | H16: 73 days | J16: 12
B17: 13 | C17: 45634 | D17: Ishan Salary | E17: 45000 | G17: Growth | J17: 13
B18: 14 | C18: 45644 | D18: Medicine | E18: 82270 | G18: Date | H18: Count | I18: Days | J18: 14
B19: 15 | G19: 45602 | H19: 130 | I19: =IF(ISBLANK(G19),"",CONCATENATE(G19-$H$15+1," days")) -> 42 days | J19: 15
B20: 16 | G20: 45608 | H20: 99 | I20: =IF(ISBLANK(G20),"",CONCATENATE(G20-$H$15+1," days")) -> 48 days | J20: 16
B21: 17 | G21: 45614 | H21: 80 | I21: =IF(ISBLANK(G21),"",CONCATENATE(G21-$H$15+1," days")) -> 54 days | J21: 17
B22: 18 | G22: 45619 | H22: 71 | I22: =IF(ISBLANK(G22),"",CONCATENATE(G22-$H$15+1," days")) -> 59 days | J22: 18
B23: 19 | G23: 45624 | H23: 61 | I23: =IF(ISBLANK(G23),"",CONCATENATE(G23-$H$15+1," days")) -> 64 days | J23: 19
B24: 20 | G24: 45631 | H24: 60 | I24: =IF(ISBLANK(G24),"",CONCATENATE(G24-$H$15+1," days")) -> 71 days | J24: 20
B25: 21 | G25: 45633 | H25: 56 | I25: =IF(ISBLANK(G25),"",CONCATENATE(G25-$H$15+1," days")) -> 73 days | J25: 21
B26: 22 | I26: =IF(ISBLANK(G26),"",CONCATENATE(G26-$H$15+1," days")) | J26: 22
B27: 23 | J27: 23
B28: 24 | J28: 24
B29: 25 | J29: 25
E31: Total Seed: | F31: 700000 | G31: Big Tank: | H31: 900000 | I31: Small Tank: | J31: 150000
E32: Trip | F32: Number | G32: Count | H32: Quantity | I32: Price | J32: Total | L32: Cash Credits
E33: 1st Middle | F33: =H33*G33 -> 163537.9 | G33: 79 | H33: 2070.1 | I33: 270 | J33: =H33*I33 -> 558927 | L33: Surya Account | M33: 200000
E34: Big Tank-Final | F34: =H34*G34 -> 300293.5 | G34: 65 | H34: 4619.9 | I34: 320 | J34: =H34*I34 -> 1478368 | L34: Lease | M34: 200000
E35: Small Tank | F35: =H35*G35 -> 62227.2 | G35: 56 | H35: 1111.2 | I35: 340 | J35: =H35*I35 -> 377808 | L35: Cash | M35: 158927
F36: =H36*G36 -> 0 | J36: =H36*I36 -> 0 | L36: Feed Shop | M36: 900000
F37: =H37*G37 -> 0 | J37: =H37*I37 -> 0 | L37: Seed | M37: 200000
F38: =H38*G38 -> 0 | J38: =H38*I38 -> 0 | L38: Cash | M38: 300000
F39: =H39*G39 -> 0 | J39: =H39*I39 -> 0 | L39: Medicine | M39: 82270
E40: Total: | F40: =SUM(F33:F38) -> 526058.6 | H40: =SUM(H33:H39) -> 7801.2 | J40: =SUM(J33:J39) -> 2415103 | L40: Total: | M40: =SUM(M33:M39) -> 2041197
E41: Number Found | F41: =CONCATENATE(ROUND((F40/F31)*100,2),"%") -> 75.15% | L41: Balance: | M41: =J40-M40 -> 373906
...

Sheet Term-7
B1: Dec2024 - Feb2025 | G1: Seed Date | H1: 45631 | J1: Profit | K1: =M2-E2 -> 528979
D2: Total : | E2: =SUM(E5:E30) -> 1502849 | G2: Days | H2: 79 days | L2: Total : | M2: =SUM(M5:M22) -> 2031828
B3: Investment | G3: Growth | J3: Income
B4: # | C4: Date | D4: Item | E4: Amount | F4: Details | G4: Date | H4: Count | I4: Days | J4: # | K4: Date | L4: Item | M4: Amount | N4: Details
B5: 1 | C5: 45631 | D5: Big Tank Seed | E5: 265000 | F5: From Pondichery(8L) | G5: 45692 | H5: 137 | I5: =IF(ISBLANK(G5),"",CONCATENATE(G5-$H$1+1," days")) -> 62 days | J5: 1 | K5: 45701 | L5: 1st Middle: Tones 2149.5-Rs.245 Count-110 | M5: 526628
B6: 2 | C6: 45631 | D6: Kirayi | E6: 38941 | G6: 45701 | H6: 110 | I6: =IF(ISBLANK(G6),"",CONCATENATE(G6-$H$1+1," days")) -> 71 days | J6: 2 | K6: 45709 | L6: Big Tank-Final-5220T-260R-100C | M6: 1357200
B7: 3 | C7: 45677 | D7: Current Bill | E7: 23950 | G7: 45708 | H7: 100 | I7: =IF(ISBLANK(G7),"",CONCATENATE(G7-$H$1+1," days")) -> 78 days | J7: 3 | K7: 45717 | L7: Small Tank-600Q-200R-135C | M7: 148000
B8: 4 | C8: 45653 | D8: Small Tank Seed | E8: 40000 | F8: From Kakinada(1.25L) | G8: 45709 | H8: 97 | I8: =IF(ISBLANK(G8),"",CONCATENATE(G8-$H$1+1," days")) -> 79 days | J8: 4
B9: 5 | C9: 45701 | D9: Middle Expenses | E9: 8000 | I9: =IF(ISBLANK(G9),"",CONCATENATE(G9-$H$1+1," days")) | J9: 5
B10: 6 | C10: 45705 | D10: Current Bill | E10: 31958 | I10: =IF(ISBLANK(G10),"",CONCATENATE(G10-$H$1+1," days")) | J10: 6
B11: 7 | C11: 45714 | D11: Feed | E11: 1095000 | I11: =IF(ISBLANK(G11),"",CONCATENATE(G11-$H$1+1," days")) | J11: 7
B12: 8 | I12: =IF(ISBLANK(G12),"",CONCATENATE(G12-$H$1+1," days")) | J12: 8
B13: 9 | I13: =IF(ISBLANK(G13),"",CONCATENATE(G13-$H$1+1," days")) | J13: 9
B14: 10 | G14: Small Tank | J14: 10
B15: 11 | G15: Seed Date | H15: 45653 | J15: 11
B16: 12 | G16: Days | H16: 65 days | J16: 12
B17: 13 | G17: Growth | J17: 13
B18: 14 | G18: Date | H18: Count | I18: Days | J18: 14
B19: 15 | G19: 45692 | H19: 240 | I19: =IF(ISBLANK(G19),"",CONCATENATE(G19-$H$15+1," days")) -> 40 days | J19: 15
B20: 16 | G20: 45700 | H20: 186 | I20: =IF(ISBLANK(G20),"",CONCATENATE(G20-$H$15+1," days")) -> 48 days | J20: 16
B21: 17 | G21: 45708 | H21: 142 | I21: =IF(ISBLANK(G21),"",CONCATENATE(G21-$H$15+1," days")) -> 56 days | J21: 17
B22: 18 | G22: 45714 | H22: 146 | I22: =IF(ISBLANK(G22),"",CONCATENATE(G22-$H$15+1," days")) -> 62 days | J22: 18
B23: 19 | G23: 45717 | H23: 140 | I23: =IF(ISBLANK(G23),"",CONCATENATE(G23-$H$15+1," days")) -> 65 days | J23: 19
B24: 20 | I24: =IF(ISBLANK(G24),"",CONCATENATE(G24-$H$15+1," days")) | J24: 20
B25: 21 | I25: =IF(ISBLANK(G25),"",CONCATENATE(G25-$H$15+1," days")) | J25: 21
B26: 22 | J26: 22
B27: 23 | J27: 23
B28: 24 | J28: 24
B29: 25 | J29: 25
E31: Total Seed: | F31: 925000 | G31: Big Tank: | H31: 900000 | I31: Small Tank: | J31: 150000
E32: Trip | F32: Number | G32: Count | H32: Quantity | I32: Price | J32: Total | L32: Cash Credits
E33: 1st Middle | F33: =H33*G33 -> 236445 | G33: 110 | H33: 2149.5 | I33: 245 | J33: =H33*I33 -> 526627.5 | L33: Surya Account | M33: 200000
E34: Big Tank-Final | F34: =H34*G34 -> 506340 | G34: 97 | H34: 5220 | I34: 260 | J34: =H34*I34 -> 1357200 | L34: Surya Account | M34: 50000
E35: Small Tank | F35: =H35*G35 -> 99900 | G35: 135 | H35: 740 | I35: 200 | J35: =H35*I35 -> 148000 | L35: Surya Account | M35: 200000
F36: =H36*G36 -> 0 | J36: =H36*I36 -> 0 | L36: Feed | M36: 1095000
F37: =H37*G37 -> 0 | J37: =H37*I37 -> 0 | L37: Seed | M37: 240000
F38: =H38*G38 -> 0 | J38: =H38*I38 -> 0 | L38: Cash | M38: 274600
F39: =H39*G39 -> 0 | J39: =H39*I39 -> 0
E40: Total: | F40: =SUM(F33:F38) -> 842685 | H40: =SUM(H33:H39) -> 8109.5 | J40: =SUM(J33:J39) -> 2031827.5 | L40: Total: | M40: =SUM(M33:M39) -> 2059600
E41: Number Found | F41: =CONCATENATE(ROUND((F40/F31)*100,2),"%") -> 91.1% | L41: Balance: | M41: =J40-M40 -> -27772.5
...

Sheet Term-8
B1: Feb2025 - May2025 | G1: Seed Date | H1: 45714 | J1: Profit | K1: =M2-E2 -> 405496
D2: Total : | E2: =SUM(E5:E30) -> 1386194 | G2: Days | H2: 78 days | L2: Total : | M2: =SUM(M5:M22) -> 1791690
B3: Investment | G3: Growth | J3: Income
B4: # | C4: Date | D4: Item | E4: Amount | F4: Details | G4: Date | H4: Count | I4: Days | J4: # | K4: Date | L4: Item | M4: Amount | N4: Details
B5: 1 | C5: 45714 | D5: Seed for Big Tank | E5: 257500 | F5: 750000 - From Gudur | G5: 45765 | H5: 157 | I5: =IF(ISBLANK(G5),"",CONCATENATE(G5-$H$1+1," days")) -> 52 days | J5: 1 | K5: 45775 | L5: 1st Middle - 110C-220R-1674T | M5: 368280
B6: 2 | C6: 45743 | D6: Seed for Small Tank | E6: 35000 | F6: 100000 - From Gudur | G6: 45775 | H6: 110 | I6: =IF(ISBLANK(G6),"",CONCATENATE(G6-$H$1+1," days")) -> 62 days | J6: 2 | K6: 45787 | L6: 2nd Middle - 73C-265R-2194.4T | M6: 571064
B7: 3 | C7: 45792 | D7: 10.5 tons feed so far | E7: 984721 | G7: 45783 | H7: 86 | I7: =IF(ISBLANK(G7),"",CONCATENATE(G7-$H$1+1," days")) -> 70 days | J7: 3 | K7: 45791 | L7: Big Tank - Final - 67C-280R-2425T | M7: 679140
B8: 4 | C8: 45792 | D8: Cash Investment | E8: 108973 | G8: 45787 | H8: 74 | I8: =IF(ISBLANK(G8),"",CONCATENATE(G8-$H$1+1," days")) -> 74 days | J8: 4 | K8: 45791 | L8: Small Tank - Final-100C-220R-787Q | M8: 173206
B9: 5 | G9: 45791 | H9: 67 | I9: =IF(ISBLANK(G9),"",CONCATENATE(G9-$H$1+1," days")) -> 78 days | J9: 5
B10: 6 | D10: 900 | I10: =IF(ISBLANK(G10),"",CONCATENATE(G10-$H$1+1," days")) | J10: 6
B11: 7 | D11: 2400 | I11: =IF(ISBLANK(G11),"",CONCATENATE(G11-$H$1+1," days")) | J11: 7
B12: 8 | D12: 25261 | I12: =IF(ISBLANK(G12),"",CONCATENATE(G12-$H$1+1," days")) | J12: 8
B13: 9 | D13: 3360 | I13: =IF(ISBLANK(G13),"",CONCATENATE(G13-$H$1+1," days")) | J13: 9
B14: 10 | D14: 6000 | G14: Small Tank | J14: 10
B15: 11 | D15: 6000 | G15: Seed Date | H15: 45743 | J15: 11
B16: 12 | D16: 4956 | G16: Days | H16: 48 days | J16: 12
B17: 13 | D17: 5600 | G17: Growth | J17: 13
B18: 14 | D18: 3000 | G18: Date | H18: Count | I18: Days | J18: 14
B19: 15 | D19: 26577 | G19: 45783 | H19: 132 | I19: =IF(ISBLANK(G19),"",CONCATENATE(G19-$H$15+1," days")) -> 41 days | J19: 15
B20: 16 | D20: 24919 | G20: 45791 | H20: 102 | I20: =IF(ISBLANK(G20),"",CONCATENATE(G20-$H$15+1," days")) -> 49 days | J20: 16
B21: 17 | I21: =IF(ISBLANK(G21),"",CONCATENATE(G21-$H$15+1," days")) | J21: 17
B22: 18 | I22: =IF(ISBLANK(G22),"",CONCATENATE(G22-$H$15+1," days")) | J22: 18
B23: 19 | I23: =IF(ISBLANK(G23),"",CONCATENATE(G23-$H$15+1," days")) | J23: 19
B24: 20 | I24: =IF(ISBLANK(G24),"",CONCATENATE(G24-$H$15+1," days")) | J24: 20
B25: 21 | I25: =IF(ISBLANK(G25),"",CONCATENATE(G25-$H$15+1," days")) | J25: 21
B26: 22 | J26: 22
B27: 23 | J27: 23
B28: 24 | J28: 24
B29: 25 | J29: 25
E31: Total Seed: | F31: 850000 | G31: Big Tank: | H31: 900000 | I31: Small Tank: | J31: 150000
E32: Trip | F32: Number | G32: Count | H32: Quantity | I32: Price | J32: Total | L32: Cash Credits
E33: 1st Middle | F33: =H33*G33 -> 184140 | G33: 110 | H33: 1674 | I33: 220 | J33: =H33*I33 -> 368280 | L33: Reddy Garu - Advance | M33: 400000
E34: 2nd Middle | F34: =H34*G34 -> 160337.2 | G34: 73 | H34: 2196.4 | I34: 260 | J34: =H34*I34 -> 571064 | L34: Surya Account - 24/05/2025 | M34: 200000
E35: Big Tank - Final | F35: =H35*G35 -> 162508.5 | G35: 67 | H35: 2425.5 | I35: 280 | J35: =H35*I35 -> 679140 | L35: Liquid Cash - 27/05/2025 | M35: 250000
E36: Small Tank | F36: =H36*G36 -> 80304.6 | G36: 102 | H36: 787.3 | I36: 220 | J36: =H36*I36 -> 173206 | L36: Feed - 10.5 Tons | M36: 985721
F37: 0 | J37: =H37*I37 -> 0
F38: =H38*G38 -> 0 | J38: =H38*I38 -> 0
F39: =H39*G39 -> 0 | J39: =H39*I39 -> 0
E40: Total: | F40: =SUM(F33:F38) -> 587290.3 | H40: =SUM(H33:H39) -> 7083.2 | J40: =SUM(J33:J39) -> 1791690 | L40: Total: | M40: =SUM(M33:M39) -> 1835721
E41: Number Found | F41: =CONCATENATE(ROUND((F40/F31)*100,2),"%") -> 69.09% | L41: Balance: | M41: =J40-M40 -> -44031
...

Sheet Term-9
B1: July2025 - Sept2025 | G1: Seed Date | H1: 45840 | J1: Profit | K1: =M2-E2 -> 1125929.5
D2: Total : | E2: =SUM(E5:E30) -> 1410000 | G2: Days | H2: 62 days | L2: Total : | M2: =SUM(M5:M22) -> 2535929.5
B3: Investment | G3: Growth | J3: Income
B4: # | C4: Date | D4: Item | E4: Amount | F4: Details | G4: Date | H4: Count | I4: Days | J4: # | K4: Date | L4: Item | M4: Amount | N4: Details
B5: 1 | C5: 45840 | D5: Seed for Big Tank | E5: 300000 | F5: 1068 packets from Kakinada | G5: 45884 | H5: 135 | I5: =IF(ISBLANK(G5),"",CONCATENATE(G5-$H$1+1," days")) -> 45 days | J5: 1 | K5: 45893 | L5: 1st Middle - 100C-245R-2171T | M5: 521040
B6: 2 | D6: Cash Investment | E6: 160000 | G6: 45889 | H6: 120 | I6: =IF(ISBLANK(G6),"",CONCATENATE(G6-$H$1+1," days")) -> 50 days | J6: 2 | K6: 45900 | L6: 2nd Middle - 80C-265R-2854.7T | M6: 756496
B7: 3 | D7: Feed so far 10 tones | E7: 920000 | G7: 45893 | H7: 98 | I7: =IF(ISBLANK(G7),"",CONCATENATE(G7-$H$1+1," days")) -> 54 days | J7: 3 | K7: 45901 | L7: Big Tank-Final - 80C-265R-3548.7T | M7: 940405.5 | N7: Virus
B8: 4 | D8: Assam Salary | E8: 30000 | G8: 45899 | H8: 78 | I8: =IF(ISBLANK(G8),"",CONCATENATE(G8-$H$1+1," days")) -> 60 days | J8: 4 | K8: 45912 | L8: Small Tank-Final-50C-330R-900K | M8: 317988
B9: 5 | G9: 45900 | H9: 81 | I9: =IF(ISBLANK(G9),"",CONCATENATE(G9-$H$1+1," days")) -> 61 days | J9: 5
B10: 6 | G10: 45901 | H10: 79 | I10: =IF(ISBLANK(G10),"",CONCATENATE(G10-$H$1+1," days")) -> 62 days | J10: 6
B11: 7 | I11: =IF(ISBLANK(G11),"",CONCATENATE(G11-$H$1+1," days")) | J11: 7
B12: 8 | I12: =IF(ISBLANK(G12),"",CONCATENATE(G12-$H$1+1," days")) | J12: 8
B13: 9 | I13: =IF(ISBLANK(G13),"",CONCATENATE(G13-$H$1+1," days")) | J13: 9
B14: 10 | G14: Small Tank | J14: 10
B15: 11 | G15: Seed Date | H15: 45840 | J15: 11
B16: 12 | G16: Days | H16: 73 days | J16: 12
B17: 13 | G17: Growth | J17: 13
B18: 14 | G18: Date | H18: Count | I18: Days | J18: 14
B19: 15 | G19: 45884 | H19: 150 | I19: =IF(ISBLANK(G19),"",CONCATENATE(G19-$H$15+1," days")) -> 45 days | J19: 15
B20: 16 | G20: 45889 | H20: 120 | I20: =IF(ISBLANK(G20),"",CONCATENATE(G20-$H$15+1," days")) -> 50 days | J20: 16
B21: 17 | G21: 45893 | H21: 97 | I21: =IF(ISBLANK(G21),"",CONCATENATE(G21-$H$15+1," days")) -> 54 days | J21: 17
B22: 18 | G22: 45899 | H22: 80 | I22: =IF(ISBLANK(G22),"",CONCATENATE(G22-$H$15+1," days")) -> 60 days | J22: 18
B23: 19 | G23: 45900 | H23: 74 | I23: =IF(ISBLANK(G23),"",CONCATENATE(G23-$H$15+1," days")) -> 61 days | J23: 19
B24: 20 | G24: 45907 | H24: 56 | I24: =IF(ISBLANK(G24),"",CONCATENATE(G24-$H$15+1," days")) -> 68 days | J24: 20
B25: 21 | G25: 45910 | H25: 50 | I25: =IF(ISBLANK(G25),"",CONCATENATE(G25-$H$15+1," days")) -> 71 days | J25: 21
B26: 22 | G26: 45912 | H26: 48 | I26: =IF(ISBLANK(G26),"",CONCATENATE(G26-$H$15+1," days")) -> 73 days | J26: 22
B27: 23 | J27: 23
B28: 24 | J28: 24
B29: 25 | J29: 25
E31: Total Seed: | F31: 1050000 | G31: Big Tank: | H31: 900000 | I31: Small Tank: | J31: 150000
E32: Trip | F32: Number | G32: Count | H32: Quantity | I32: Price | J32: Total | L32: Cash Credits
E33: 1st Middle - Big Tank | F33: =H33*G33 -> 190815.8 | G33: 98 | H33: 1947.1 | I33: 240 | J33: =H33*I33 -> 467304 | L33: Surya Account - 02-09-2025 | M33: 100000
E34: 1st Middle - Small Tank | F34: =H34*G34 -> 21718.3 | G34: 97 | H34: 223.9 | I34: 240 | J34: =H34*I34 -> 53736 | L34: Cash - 06-09-2025 | M34: 600000
E35: 2nd Middle - Big Tank | F35: =H35*G35 -> 185004 | G35: 81 | H35: 2284 | I35: 265 | J35: =H35*I35 -> 605260 | L35: Cash - 13-09-2025 | M35: 700000
E36: 2nd Middle - Small Tank | F36: =H36*G36 -> 42231.8 | G36: 74 | H36: 570.7 | I36: 265 | J36: =H36*I36 -> 151235.5 | L36: Feed | M36: 920000
E37: Final - Big Tank | F37: =H37*G37 -> 280347.3 | G37: 79 | H37: 3548.7 | I37: 265 | J37: =H37*I37 -> 940405.5 | L37: Bend shape 6% | M37: 16000
E38: Final - Small Tank | F38: =H38*G38 -> 46252.8 | G38: 48 | H38: 963.6 | I38: 330 | J38: =H38*I38 -> 317988 | L38: Seed - 17-09-2025 | M38: 200000
F39: =H39*G39 -> 0 | J39: =H39*I39 -> 0
E40: Total: | F40: =SUM(F33:F38) -> 766370 | H40: =SUM(H33:H39) -> 9538 | J40: =SUM(J33:J39) -> 2535929 | L40: Total: | M40: =SUM(M33:M39) -> 2536000
E41: Number Found | F41: =CONCATENATE(ROUND((F40/F31)*100,2),"%") -> 72.99% | L41: Balance: | M41: =J40-M40 -> -71
...

Sheet Term-10
B1: Sept2025 - Dec2025 | G1: Seed Date | H1: 45918 | J1: Profit | K1: =M2-E2 -> 979350
D2: Total : | E2: =SUM(E5:E30) -> 1551000 | G2: Days | H2: 78 days | L2: Total : | M2: =SUM(M5:M22) -> 2530350
B3: Investment | G3: Growth | J3: Income
B4: # | C4: Date | D4: Item | E4: Amount | F4: Details | G4: Date | H4: Count | I4: Days | J4: # | K4: Date | L4: Item | M4: Amount | N4: Details
B5: 1 | C5: 45918 | D5: Seed | E5: 288000 | F5: 9L seed from Gudur | G5: 45972 | H5: 90 | I5: =IF(ISBLANK(G5),"",CONCATENATE(G5-$H$1+1," days")) -> 55 days | J5: 1 | K5: 45975 | L5: Big Tank-1st Middle - 90C-240R-2000T | M5: 496056
B6: 2 | C6: 45918 | D6: Seed Transport | E6: 17500 | G6: 45974 | H6: 93 | I6: =IF(ISBLANK(G6),"",CONCATENATE(G6-$H$1+1," days")) -> 57 days | J6: 2 | K6: 45985 | L6: Big Tank-2nd Middle - 70C-300R-2000T | M6: 644160
B7: 3 | C7: 45961 | D7: Feed - 12 Tons so far | E7: 996000 | G7: 45975 | H7: 88 | I7: =IF(ISBLANK(G7),"",CONCATENATE(G7-$H$1+1," days")) -> 58 days | J7: 3 | K7: 45995 | L7: Big Tank-Final - 60C-335R-3392.8T | M7: 1136588
B8: 4 | C8: 45956 | D8: Diesel | E8: 15000 | G8: 45982 | H8: 72 | I8: =IF(ISBLANK(G8),"",CONCATENATE(G8-$H$1+1," days")) -> 65 days | J8: 4 | K8: 45995 | L8: Small Tank-Final-80C-265R-857.1K | M8: 244273.5
B9: 5 | C9: 45995 | D9: Extra Medicine | E9: 100000 | G9: 45985 | H9: 68 | I9: =IF(ISBLANK(G9),"",CONCATENATE(G9-$H$1+1," days")) -> 68 days | J9: 5 | K9: 46001 | L9: Big Tank - Extra | M9: 3182.5
B10: 6 | C10: 45995 | D10: Cash | E10: 70000 | G10: 45991 | H10: 62 | I10: =IF(ISBLANK(G10),"",CONCATENATE(G10-$H$1+1," days")) -> 74 days | J10: 6 | K10: 46003 | L10: Small Tank - Extra | M10: 6090
B11: 7 | C11: 45995 | D11: Current bill | E11: 34500 | G11: 45995 | H11: 58 | I11: =IF(ISBLANK(G11),"",CONCATENATE(G11-$H$1+1," days")) -> 78 days | J11: 7
B12: 8 | C12: 45995 | D12: Assam salary | E12: 30000 | I12: =IF(ISBLANK(G12),"",CONCATENATE(G12-$H$1+1," days")) | J12: 8
B13: 9 | I13: =IF(ISBLANK(G13),"",CONCATENATE(G13-$H$1+1," days")) | J13: 9
B14: 10 | G14: Small Tank | J14: 10
B15: 11 | G15: Seed Date | H15: 45918 | J15: 11
B16: 12 | G16: Days | H16: 78 days | J16: 12
B17: 13 | G17: Growth | J17: 13
B18: 14 | G18: Date | H18: Count | I18: Days | J18: 14
B19: 15 | G19: 45972 | H19: 130 | I19: =IF(ISBLANK(G19),"",CONCATENATE(G19-$H$15+1," days")) -> 55 days | J19: 15
B20: 16 | G20: 45979 | H20: 110 | I20: =IF(ISBLANK(G20),"",CONCATENATE(G20-$H$15+1," days")) -> 62 days | J20: 16
B21: 17 | G21: 45991 | H21: 93 | I21: =IF(ISBLANK(G21),"",CONCATENATE(G21-$H$15+1," days")) -> 74 days | J21: 17
B22: 18 | G22: 45995 | H22: 78 | I22: =IF(ISBLANK(G22),"",CONCATENATE(G22-$H$15+1," days")) -> 78 days | J22: 18
B23: 19 | I23: =IF(ISBLANK(G23),"",CONCATENATE(G23-$H$15+1," days")) | J23: 19
B24: 20 | I24: =IF(ISBLANK(G24),"",CONCATENATE(G24-$H$15+1," days")) | J24: 20
B25: 21 | I25: =IF(ISBLANK(G25),"",CONCATENATE(G25-$H$15+1," days")) | J25: 21
B26: 22 | J26: 22
B27: 23 | J27: 23
B28: 24 | J28: 24
B29: 25 | J29: 25
E31: Total Seed: | F31: 900000 | G31: Big Tank: | H31: 750000 | I31: Small Tank: | J31: 150000
E32: Trip | F32: Number | G32: Count | H32: Quantity | I32: Price | J32: Total | L32: Cash Credits
E33: Big Tank-1st Middle | F33: =H33*G33 -> 181887.2 | G33: 88 | H33: 2066.9 | I33: 240 | J33: =H33*I33 -> 496056 | L33: Surya Account - | M33: 50000
E34: Big Tank- 2nd Middle | F34: =H34*G34 -> 146009.6 | G34: 68 | H34: 2147.2 | I34: 300 | J34: =H34*I34 -> 644160 | L34: Feed | M34: 996688
E35: Big Tank - Final | F35: =H35*G35 -> 196782.4 | G35: 58 | H35: 3392.8 | I35: 335 | J35: =H35*I35 -> 1136588 | L35: Cash - 18-12-2025 | M35: 500000
E36: Small Tank - Final | F36: =H36*G36 -> 66853.8 | G36: 78 | H36: 857.1 | I36: 285 | J36: =H36*I36 -> 244273.5 | L36: Cash - 24-12-2025 | M36: 500000
E37: Big Tank - Extra | F37: =H37*G37 -> 570 | G37: 60 | H37: 9.5 | I37: 335 | J37: =H37*I37 -> 3182.5 | L37: Seed - 24-12-2025 | M37: 300000
E38: Small Tank - Extra | F38: =H38*G38 -> 1680 | G38: 80 | H38: 21 | I38: 290 | J38: =H38*I38 -> 6090 | L38: Surya Account - | M38: 50000
F39: =H39*G39 -> 0 | J39: =H39*I39 -> 0 | L39: Cash | M39: 136000
E40: Total: | F40: =SUM(F33:F38) -> 593783 | H40: =SUM(H33:H39) -> 8494.5 | J40: =SUM(J33:J39) -> 2530350 | L40: Total: | M40: =SUM(M33:M39) -> 2532688
E41: Number Found | F41: =CONCATENATE(ROUND((F40/F31)*100,2),"%") -> 65.98% | L41: Balance: | M41: =J40-M40 -> -2338
...

Sheet Term-11
B1: Dec2025 - Jan2026 | G1: Seed Date | H1: 46016 | J1: Profit | K1: =M2-E2 -> -469722.5
D2: Total : | E2: =SUM(E5:E30) -> 585000 | G2: Days | H2: 34 days | L2: Total : | M2: =SUM(M5:M22) -> 115277.5
B3: Investment | G3: Growth | J3: Income
B4: # | C4: Date | D4: Item | E4: Amount | F4: Details | G4: Date | H4: Count | I4: Days | J4: # | K4: Date | L4: Item | M4: Amount | N4: Details
B5: 1 | C5: 46016 | D5: Seed | E5: 288000 | F5: from Kakinada-9L (990 ballons) | G5: 46049 | H5: 518 | I5: =IF(ISBLANK(G5),"",CONCATENATE(G5-$H$1+1," days")) -> 34 days | J5: 1 | K5: 46046 | L5: Small Tank Full | M5: 0 | N5: virus
B6: 2 | C6: 46016 | D6: Van Kiray | E6: 13000 | I6: =IF(ISBLANK(G6),"",CONCATENATE(G6-$H$1+1," days")) | J6: 2 | K6: 46049 | L6: Big Tank Full | M6: 115277.5 | N6: virus
B7: 3 | C7: 46046 | D7: Feed-2.5T | E7: 250000 | I7: =IF(ISBLANK(G7),"",CONCATENATE(G7-$H$1+1," days")) | J7: 3
B8: 4 | C8: 46046 | D8: Current bill | E8: 34000 | I8: =IF(ISBLANK(G8),"",CONCATENATE(G8-$H$1+1," days")) | J8: 4
B9: 5 | I9: =IF(ISBLANK(G9),"",CONCATENATE(G9-$H$1+1," days")) | J9: 5
B10: 6 | I10: =IF(ISBLANK(G10),"",CONCATENATE(G10-$H$1+1," days")) | J10: 6
B11: 7 | I11: =IF(ISBLANK(G11),"",CONCATENATE(G11-$H$1+1," days")) | J11: 7
B12: 8 | I12: =IF(ISBLANK(G12),"",CONCATENATE(G12-$H$1+1," days")) | J12: 8
B13: 9 | I13: =IF(ISBLANK(G13),"",CONCATENATE(G13-$H$1+1," days")) | J13: 9
B14: 10 | G14: Small Tank | J14: 10
B15: 11 | G15: Seed Date | H15: 46016 | J15: 11
B16: 12 | G16: Days | H16: 31 days | J16: 12
B17: 13 | G17: Growth | J17: 13
B18: 14 | G18: Date | H18: Count | I18: Days | J18: 14
B19: 15 | I19: =IF(ISBLANK(G19),"",CONCATENATE(G19-$H$15+1," days")) | J19: 15
B20: 16 | I20: =IF(ISBLANK(G20),"",CONCATENATE(G20-$H$15+1," days")) | J20: 16
B21: 17 | I21: =IF(ISBLANK(G21),"",CONCATENATE(G21-$H$15+1," days")) | J21: 17
B22: 18 | I22: =IF(ISBLANK(G22),"",CONCATENATE(G22-$H$15+1," days")) | J22: 18
B23: 19 | I23: =IF(ISBLANK(G23),"",CONCATENATE(G23-$H$15+1," days")) | J23: 19
B24: 20 | I24: =IF(ISBLANK(G24),"",CONCATENATE(G24-$H$15+1," days")) | J24: 20
B25: 21 | I25: =IF(ISBLANK(G25),"",CONCATENATE(G25-$H$15+1," days")) | J25: 21
B26: 22 | J26: 22
B27: 23 | J27: 23
B28: 24 | J28: 24
B29: 25 | J29: 25
E31: Total Seed: | F31: 990000 | G31: Big Tank: | H31: 830000 | I31: Small Tank: | J31: 160000
E32: Trip | F32: Number | G32: Count | H32: Quantity | I32: Price | J32: Total | L32: Cash Credits
E33: Big Tank Full | F33: =H33*G33 -> 918673 | G33: 518 | H33: 1773.5 | I33: 65 | J33: =H33*I33 -> 115277.5 | L33: Feed | M33: 250000
F34: =H34*G34 -> 0 | J34: =H34*I34 -> 0
F35: =H35*G35 -> 0 | J35: =H35*I35 -> 0
F36: =H36*G36 -> 0 | J36: =H36*I36 -> 0
F37: =H37*G37 -> 0 | J37: =H37*I37 -> 0
F38: =H38*G38 -> 0 | J38: =H38*I38 -> 0
F39: =H39*G39 -> 0 | J39: =H39*I39 -> 0
E40: Total: | F40: =SUM(F33:F38) -> 918673 | H40: =SUM(H33:H39) -> 1773.5 | J40: =SUM(J33:J39) -> 115277.5 | L40: Total: | M40: =SUM(M33:M39) -> 250000
E41: Number Found | F41: =CONCATENATE(ROUND((F40/F31)*100,2),"%") -> 92.8% | L41: Balance: | M41: =J40-M40 -> -134722.5
...

Sheet Term-12
B1: Feb2026 - Apr2026 | G1: Seed Date | H1: 46068 | J1: Profit | K1: =M2-E2 -> 610376
D2: Total : | E2: =SUM(E5:E30) -> 1578900 | G2: Days | H2: 71 days | L2: Total : | M2: =SUM(M5:M22) -> 2189276
B3: Investment | G3: Growth | J3: Income
B4: # | C4: Date | D4: Item | E4: Amount | F4: Details | G4: Date | H4: Count | I4: Days | J4: # | K4: Date | L4: Item | M4: Amount | N4: Details
B5: 1 | C5: 46068 | D5: Seed | E5: 256000 | G5: 46124 | H5: 166 | I5: =IF(ISBLANK(G5),"",CONCATENATE(G5-$H$1+1," days")) -> 57 days | J5: 1 | K5: 46132 | L5: Big Tank-1st Middle - 131C-234R-1950T | M5: 456768
B6: 2 | C6: 46068 | D6: Van Kiray | E6: 33000 | F6: Gas Drums | G6: 46127 | H6: 150 | I6: =IF(ISBLANK(G6),"",CONCATENATE(G6-$H$1+1," days")) -> 60 days | J6: 2 | K6: 46138 | L6: Big Tank-Final-120C-250R-6017T | M6: 1524733
B7: 3 | C7: 46072 | D7: Current Bill | E7: 38672 | G7: 46131 | H7: 133 | I7: =IF(ISBLANK(G7),"",CONCATENATE(G7-$H$1+1," days")) -> 64 days | J7: 3 | K7: 46138 | L7: Small Tank-Final-90C-280R-650Q | M7: 207775
B8: 4 | C8: 46067 | D8: Current Bill | E8: 15813 | G8: 46132 | H8: 131 | I8: =IF(ISBLANK(G8),"",CONCATENATE(G8-$H$1+1," days")) -> 65 days | J8: 4
B9: 5 | C9: 46107 | D9: Diesel | E9: 6000 | G9: 46136 | H9: 126 | I9: =IF(ISBLANK(G9),"",CONCATENATE(G9-$H$1+1," days")) -> 69 days | J9: 5
B10: 6 | C10: 46111 | D10: Feed | E10: 1030055 | F10: 11 tons so far | G10: 46137 | H10: 125 | I10: =IF(ISBLANK(G10),"",CONCATENATE(G10-$H$1+1," days")) -> 70 days | J10: 6
B11: 7 | C11: 46127 | D11: Current Bill | E11: 29560 | G11: 46138 | H11: 121 | I11: =IF(ISBLANK(G11),"",CONCATENATE(G11-$H$1+1," days")) -> 71 days | J11: 7
B12: 8 | C12: 46127 | D12: Medicine | E12: 100000 | I12: =IF(ISBLANK(G12),"",CONCATENATE(G12-$H$1+1," days")) | J12: 8
B13: 9 | C13: 46138 | D13: Vala kIray | E13: 20800 | I13: =IF(ISBLANK(G13),"",CONCATENATE(G13-$H$1+1," days")) | J13: 9
B14: 10 | C14: 46138 | D14: Adjustments | E14: 4000 | G14: Small Tank | J14: 10
B15: 11 | C15: 46138 | D15: Assam Salary | E15: 45000 | G15: Seed Date | H15: 46068 | J15: 11
B16: 12 | G16: Days | H16: 71 days | J16: 12
B17: 13 | G17: Growth | J17: 13
B18: 14 | G18: Date | H18: Count | I18: Days | J18: 14
B19: 15 | G19: 46124 | H19: 135 | I19: =IF(ISBLANK(G19),"",CONCATENATE(G19-$H$15+1," days")) -> 57 days | J19: 15
B20: 16 | G20: 46131 | H20: 97 | I20: =IF(ISBLANK(G20),"",CONCATENATE(G20-$H$15+1," days")) -> 64 days | J20: 16
B21: 17 | G21: 46136 | H21: 85 | I21: =IF(ISBLANK(G21),"",CONCATENATE(G21-$H$15+1," days")) -> 69 days | J21: 17
B22: 18 | G22: 46137 | H22: 76 | I22: =IF(ISBLANK(G22),"",CONCATENATE(G22-$H$15+1," days")) -> 70 days | J22: 18
B23: 19 | G23: 46138 | H23: 90 | I23: =IF(ISBLANK(G23),"",CONCATENATE(G23-$H$15+1," days")) -> 71 days | J23: 19
B24: 20 | I24: =IF(ISBLANK(G24),"",CONCATENATE(G24-$H$15+1," days")) | J24: 20
B25: 21 | I25: =IF(ISBLANK(G25),"",CONCATENATE(G25-$H$15+1," days")) | J25: 21
B26: 22 | J26: 22
B27: 23 | J27: 23
B28: 24 | J28: 24
B29: 25 | J29: 25
E31: Total Seed: | F31: =H31+J31 -> 800000 | G31: Big Tank: | H31: 700000 | I31: Small Tank: | J31: 100000
E32: Trip | F32: Number | G32: Count | H32: Quantity | I32: Price | J32: Total | L32: Cash Credits
E33: Big Tank-1st Middle | F33: =H33*G33 -> 255712 | G33: 131 | H33: 1952 | I33: 234 | J33: =H33*I33 -> 456768 | L33: Pending from Term-11 | M33: 134360
E34: Big Tank-Final | F34: =H34*G34 -> 723967.2 | G34: 121 | H34: 5983.2 | I34: 254 | J34: =H34*I34 -> 1519732.8 | L34: Land Lease | M34: 200000
E35: Big Tank Final-Macrosis | F35: =H35*G35 -> 4500 | G35: 90 | H35: 50 | I35: 100 | J35: =H35*I35 -> 5000 | L35: Cash-24-04-2026 | M35: 50000
E36: Small Tank Final | F36: =H36*G36 -> 64350 | G36: 90 | H36: 715 | I36: 285 | J36: =H36*I36 -> 203775 | L36: Feed | M36: 1030055
E37: Small Tank Final-S/L | F37: =H37*G37 -> 3600 | G37: 90 | H37: 40 | I37: 100 | J37: =H37*I37 -> 4000 | L37: Surya Account | M37: 200000
F38: =H38*G38 -> 0 | J38: =H38*I38 -> 0
F39: =H39*G39 -> 0 | J39: =H39*I39 -> 0
E40: Total: | F40: =SUM(F33:F38) -> 1052129.2 | H40: =SUM(H33:H39) -> 8740.2 | J40: =SUM(J33:J39) -> 2189275.8 | L40: Total: | M40: =SUM(M33:M39) -> 1614415
E41: Number Found | F41: =CONCATENATE(ROUND((F40/F31)*100,2),"%") -> 131.52% | L41: Balance: | M41: =J40-M40 -> 574860.8
...

Sheet Term-13
B1: May2026 - July2026 | G1: Seed Date | H1: 46154 | J1: Profit | K1: =M2-E2 -> 76509.4
D2: Total : | E2: =SUM(E5:E30) -> 1439577 | G2: Days | H2: 69 days | L2: Total : | M2: =SUM(M5:M22) -> 1516086.4
B3: Investment | G3: Growth | J3: Income
B4: # | C4: Date | D4: Item | E4: Amount | F4: Details | G4: Date | H4: Count | I4: Days | J4: # | K4: Date | L4: Item | M4: Amount | N4: Details
B5: 1 | C5: 46154 | D5: Seed | E5: 256000 | F5: 8L from Tuni | G5: 46184 | H5: 350 | I5: =IF(ISBLANK(G5),"",CONCATENATE(G5-$H$1+1," days")) -> 31 days | J5: 1 | K5: 46214 | L5: Big Tank - First Middle - 119C-121R-2000T | M5: 388886.4
B6: 2 | C6: 46154 | D6: Van Kirayi | E6: 15000 | F6: Gas Drums | G6: 46207 | H6: 150 | I6: =IF(ISBLANK(G6),"",CONCATENATE(G6-$H$1+1," days")) -> 54 days | J6: 2 | K6: 46222 | L6: Big Tank - Final - 95C-240R-3950T | M6: 955200
B7: 3 | C7: 46152 | D7: Salt | E7: 10000 | F7: from Narsapuram | G7: 46212 | H7: 125 | I7: =IF(ISBLANK(G7),"",CONCATENATE(G7-$H$1+1," days")) -> 59 days | J7: 3 | K7: 46222 | L7: Small Tank - Final - 90C-250R-500T | M7: 172000
B8: 4 | C8: 46161 | D8: Current Bill | E8: 14953 | G8: 46214 | H8: 119 | I8: =IF(ISBLANK(G8),"",CONCATENATE(G8-$H$1+1," days")) -> 61 days | J8: 4
B9: 5 | C9: 46167 | D9: Tractor charges | E9: 3000 | F9: Small Tank | G9: 46221 | H9: 100 | I9: =IF(ISBLANK(G9),"",CONCATENATE(G9-$H$1+1," days")) -> 68 days | J9: 5
B10: 6 | C10: 46191 | D10: Feed | E10: 1039463 | F10: So far 10.8 tons | G10: 46222 | H10: 95 | I10: =IF(ISBLANK(G10),"",CONCATENATE(G10-$H$1+1," days")) -> 69 days | J10: 6
B11: 7 | C11: 46181 | D11: Current Bill | E11: 12238 | I11: =IF(ISBLANK(G11),"",CONCATENATE(G11-$H$1+1," days")) | J11: 7
B12: 8 | C12: 46190 | D12: New Boat | E12: 8000 | I12: =IF(ISBLANK(G12),"",CONCATENATE(G12-$H$1+1," days")) | J12: 8
B13: 9 | C13: 46221 | D13: Current Bill | E13: 23923 | I13: =IF(ISBLANK(G13),"",CONCATENATE(G13-$H$1+1," days")) | J13: 9
B14: 10 | C14: 46222 | D14: Harvesting | E14: 25000 | G14: Small Tank | J14: 10
B15: 11 | C15: 46222 | D15: Others | E15: 32000 | G15: Seed Date | H15: 46154 | J15: 11
B16: 12 | G16: Days | H16: 69 days | J16: 12
B17: 13 | G17: Growth | J17: 13
B18: 14 | G18: Date | H18: Count | I18: Days | J18: 14
B19: 15 | G19: 46184 | H19: 350 | I19: =IF(ISBLANK(G19),"",CONCATENATE(G19-$H$15+1," days")) -> 31 days | J19: 15
B20: 16 | G20: 46221 | H20: 90 | I20: =IF(ISBLANK(G20),"",CONCATENATE(G20-$H$15+1," days")) -> 68 days | J20: 16
B21: 17 | G21: 46222 | H21: 90 | I21: =IF(ISBLANK(G21),"",CONCATENATE(G21-$H$15+1," days")) -> 69 days | J21: 17
B22: 18 | I22: =IF(ISBLANK(G22),"",CONCATENATE(G22-$H$15+1," days")) | J22: 18
B23: 19 | I23: =IF(ISBLANK(G23),"",CONCATENATE(G23-$H$15+1," days")) | J23: 19
B24: 20 | I24: =IF(ISBLANK(G24),"",CONCATENATE(G24-$H$15+1," days")) | J24: 20
B25: 21 | I25: =IF(ISBLANK(G25),"",CONCATENATE(G25-$H$15+1," days")) | J25: 21
B26: 22 | J26: 22
B27: 23 | J27: 23
B28: 24 | J28: 24
B29: 25 | J29: 25
E31: Total Seed: | F31: =H31+J31 -> 800000 | G31: Big Tank: | H31: 700000 | I31: Small Tank: | J31: 100000
E32: Trip | F32: Number | G32: Count | H32: Quantity | I32: Price | J32: Total | L32: Cash Credits
E33: Big Tank - 1st Middle | F33: =H33*G33 -> 214247.6 | G33: 119 | H33: 1800.4 | I33: 216 | J33: =H33*I33 -> 388886.4 | L33: Feed | M33: 1039463
E34: Big Tank - Final | F34: =H34*G34 -> 373730 | G34: 95 | H34: 3934 | I34: 245 | J34: =H34*I34 -> 963830 | L34: Surya Account | M34: 800000
E35: Big Tank - Loose Shell | F35: =H35*G35 -> 3600 | G35: 90 | H35: 40 | I35: 60 | J35: =H35*I35 -> 2400
E36: Small Tank - Final | F36: =H36*G36 -> 60723 | G36: 90 | H36: 674.7 | I36: 255 | J36: =H36*I36 -> 172048.5
E37: Small Tank - Loose Shell | F37: =H37*G37 -> 1260 | G37: 90 | H37: 14 | I37: 60 | J37: =H37*I37 -> 840
F38: =H38*G38 -> 0 | J38: =H38*I38 -> 0
F39: =H39*G39 -> 0 | J39: =H39*I39 -> 0
E40: Total: | F40: =SUM(F33:F38) -> 653560.6 | H40: =SUM(H33:H39) -> 6463.1 | J40: =SUM(J33:J39) -> 1528004.9 | L40: Total: | M40: =SUM(M33:M39) -> 1839463
E41: Number Found | F41: =CONCATENATE(ROUND((F40/F31)*100,2),"%") -> 81.7% | L41: Balance: | M41: =J40-M40 -> -311458.1
...

Sheet Term-14
B1: Aug2026 - Sept2026 | G1: Seed Date | H1: 46243 | J1: Profit | K1: =M2-E2 -> 22177
D2: Total : | E2: =SUM(E5:E30) -> 781485 | G2: Days | H2: 57 days | L2: Total : | M2: =SUM(M5:M22) -> 803662
B3: Investment | G3: Growth | J3: Income
B4: # | C4: Date | D4: Item | E4: Amount | F4: Details | G4: Date | H4: Count | I4: Days | J4: # | K4: Date | L4: Item | M4: Amount | N4: Details
B5: 1 | C5: 46243 | D5: Seed | E5: 165000 | F5: From Moyyuru-5.5L | G5: 46297 | H5: 130 | I5: =IF(ISBLANK(G5),"",CONCATENATE(G5-$H$1+1," days")) -> 55 days | J5: 1 | K5: 46299 | L5: Big Tank Final | M5: 693462
B6: 2 | C6: 46243 | D6: Seed Kirayi | E6: 5000 | F6: Tanks | G6: 46299 | H6: 116 | I6: =IF(ISBLANK(G6),"",CONCATENATE(G6-$H$1+1," days")) -> 57 days | J6: 2 | K6: 46299 | L6: Small Tank Final | M6: 105600
B7: 3 | C7: 46249 | D7: Current Bill | E7: 16485 | I7: =IF(ISBLANK(G7),"",CONCATENATE(G7-$H$1+1," days")) | J7: 3 | K7: 46299 | L7: Big Tank Loose Shell | M7: 4600
B8: 4 | C8: 46281 | D8: Current Bill | E8: 15000 | I8: =IF(ISBLANK(G8),"",CONCATENATE(G8-$H$1+1," days")) | J8: 4
B9: 5 | C9: 46299 | D9: Feed | E9: 500000 | F9: 4 tonea | I9: =IF(ISBLANK(G9),"",CONCATENATE(G9-$H$1+1," days")) | J9: 5
B10: 6 | C10: 46299 | D10: Medicine | E10: 50000 | I10: =IF(ISBLANK(G10),"",CONCATENATE(G10-$H$1+1," days")) | J10: 6
B11: 7 | C11: 46299 | D11: Assam Salary | E11: 30000 | I11: =IF(ISBLANK(G11),"",CONCATENATE(G11-$H$1+1," days")) | J11: 7
B12: 8 | I12: =IF(ISBLANK(G12),"",CONCATENATE(G12-$H$1+1," days")) | J12: 8
B13: 9 | I13: =IF(ISBLANK(G13),"",CONCATENATE(G13-$H$1+1," days")) | J13: 9
B14: 10 | G14: Small Tank | J14: 10
B15: 11 | G15: Seed Date | H15: 46243 | J15: 11
B16: 12 | G16: Days | H16: 57 days | J16: 12
B17: 13 | G17: Growth | J17: 13
B18: 14 | G18: Date | H18: Count | I18: Days | J18: 14
B19: 15 | G19: 46299 | H19: 114 | I19: =IF(ISBLANK(G19),"",CONCATENATE(G19-$H$15+1," days")) -> 57 days | J19: 15
B20: 16 | I20: =IF(ISBLANK(G20),"",CONCATENATE(G20-$H$15+1," days")) | J20: 16
B21: 17 | I21: =IF(ISBLANK(G21),"",CONCATENATE(G21-$H$15+1," days")) | J21: 17
B22: 18 | I22: =IF(ISBLANK(G22),"",CONCATENATE(G22-$H$15+1," days")) | J22: 18
B23: 19 | I23: =IF(ISBLANK(G23),"",CONCATENATE(G23-$H$15+1," days")) | J23: 19
B24: 20 | I24: =IF(ISBLANK(G24),"",CONCATENATE(G24-$H$15+1," days")) | J24: 20
B25: 21 | I25: =IF(ISBLANK(G25),"",CONCATENATE(G25-$H$15+1," days")) | J25: 21
B26: 22 | J26: 22
B27: 23 | J27: 23
B28: 24 | J28: 24
B29: 25 | J29: 25
E31: Total Seed: | F31: =H31+J31 -> 550000 | G31: Big Tank: | H31: 450000 | I31: Small Tank: | J31: 100000
E32: Trip | F32: Number | G32: Count | H32: Quantity | I32: Price | J32: Total | L32: Cash Credits
E33: Big Tank Final | F33: =H33*G33 -> 297198 | G33: 114 | H33: 2607 | I33: 266 | J33: =H33*I33 -> 693462 | L33: Feed | M33: 500000
E34: Small Tank Final | F34: =H34*G34 -> 46400 | G34: 116 | H34: 400 | I34: 264 | J34: =H34*I34 -> 105600 | L34: Last Term | M34: 311458.1
E35: Loose Shell | F35: =H35*G35 -> 5244 | G35: 114 | H35: 46 | I35: 100 | J35: =H35*I35 -> 4600 | L35: Land Lease | M35: 200000
E36: Extra | F36: =H36*G36 -> 1140 | G36: 114 | H36: 10 | I36: 0 | J36: =H36*I36 -> 0
F37: =H37*G37 -> 0 | J37: =H37*I37 -> 0
F38: =H38*G38 -> 0 | J38: =H38*I38 -> 0
F39: =H39*G39 -> 0 | J39: =H39*I39 -> 0
E40: Total: | F40: =SUM(F33:F38) -> 349982 | H40: =SUM(H33:H39) -> 3063 | J40: =SUM(J33:J39) -> 803662 | L40: Total: | M40: =SUM(M33:M39) -> 1011458.1
E41: Number Found | F41: =CONCATENATE(ROUND((F40/F31)*100,2),"%") -> 63.63% | L41: Balance: | M41: =J40-M40 -> -207796.1
...

Sheet Term-15
B1: Oct2026 - Dec2026 | G1: Seed Date | H1: 46316 | J1: Profit | K1: =M2-E2 -> -300000
D2: Total : | E2: =SUM(E5:E30) -> 300000 | G2: Days | H2: =IF(ISBLANK(H1),"0 Days",CONCATENATE(_xlfn.DAYS(TODAY()+1, H1)," days")) -> 0 days | L2: Total : | M2: =SUM(M5:M22) -> 0
B3: Investment | G3: Growth | J3: Income
B4: # | C4: Date | D4: Item | E4: Amount | F4: Details | G4: Date | H4: Count | I4: Days | J4: # | K4: Date | L4: Item | M4: Amount | N4: Details
B5: 1 | C5: 46316 | D5: Seed | E5: 280000 | F5: From Ongole | I5: =IF(ISBLANK(G5),"",CONCATENATE(G5-$H$1+1," days")) | J5: 1
B6: 2 | C6: 46316 | D6: Van Kiray | E6: 20000 | F6: Narisimha murthy | I6: =IF(ISBLANK(G6),"",CONCATENATE(G6-$H$1+1," days")) | J6: 2
B7: 3 | I7: =IF(ISBLANK(G7),"",CONCATENATE(G7-$H$1+1," days")) | J7: 3
B8: 4 | I8: =IF(ISBLANK(G8),"",CONCATENATE(G8-$H$1+1," days")) | J8: 4
B9: 5 | I9: =IF(ISBLANK(G9),"",CONCATENATE(G9-$H$1+1," days")) | J9: 5
B10: 6 | I10: =IF(ISBLANK(G10),"",CONCATENATE(G10-$H$1+1," days")) | J10: 6
B11: 7 | I11: =IF(ISBLANK(G11),"",CONCATENATE(G11-$H$1+1," days")) | J11: 7
B12: 8 | I12: =IF(ISBLANK(G12),"",CONCATENATE(G12-$H$1+1," days")) | J12: 8
B13: 9 | I13: =IF(ISBLANK(G13),"",CONCATENATE(G13-$H$1+1," days")) | J13: 9
B14: 10 | G14: Small Tank | J14: 10
B15: 11 | G15: Seed Date | H15: 46316 | J15: 11
B16: 12 | G16: Days | H16: =IF(ISBLANK(H15),"0 Days",CONCATENATE(_xlfn.DAYS(TODAY()+1, H1)," days")) -> 0 days | J16: 12
B17: 13 | G17: Growth | J17: 13
B18: 14 | G18: Date | H18: Count | I18: Days | J18: 14
B19: 15 | I19: =IF(ISBLANK(G19),"",CONCATENATE(G19-$H$15+1," days")) | J19: 15
B20: 16 | I20: =IF(ISBLANK(G20),"",CONCATENATE(G20-$H$15+1," days")) | J20: 16
B21: 17 | I21: =IF(ISBLANK(G21),"",CONCATENATE(G21-$H$15+1," days")) | J21: 17
B22: 18 | I22: =IF(ISBLANK(G22),"",CONCATENATE(G22-$H$15+1," days")) | J22: 18
B23: 19 | I23: =IF(ISBLANK(G23),"",CONCATENATE(G23-$H$15+1," days")) | J23: 19
B24: 20 | I24: =IF(ISBLANK(G24),"",CONCATENATE(G24-$H$15+1," days")) | J24: 20
B25: 21 | I25: =IF(ISBLANK(G25),"",CONCATENATE(G25-$H$15+1," days")) | J25: 21
B26: 22 | J26: 22
B27: 23 | J27: 23
B28: 24 | J28: 24
B29: 25 | J29: 25
E31: Total Seed: | F31: =H31+J31 -> 0 | G31: Big Tank: | I31: Small Tank:
E32: Trip | F32: Number | G32: Count | H32: Quantity | I32: Price | J32: Total | L32: Cash Credits
F33: =H33*G33 -> 0 | J33: =H33*I33 -> 0
F34: =H34*G34 -> 0 | J34: =H34*I34 -> 0
F35: =H35*G35 -> 0 | J35: =H35*I35 -> 0
F36: =H36*G36 -> 0 | J36: =H36*I36 -> 0
F37: =H37*G37 -> 0 | J37: =H37*I37 -> 0
F38: =H38*G38 -> 0 | J38: =H38*I38 -> 0
F39: =H39*G39 -> 0 | J39: =H39*I39 -> 0
E40: Total: | F40: =SUM(F33:F38) -> 0 | H40: =SUM(H33:H39) -> 0 | J40: =SUM(J33:J39) -> 0 | L40: Total: | M40: =SUM(M33:M39) -> 0
E41: Number Found | F41: =CONCATENATE(ROUND((F40/F31)*100,2),"%") -> #DIV/0! | L41: Balance: | M41: =J40-M40 -> 0
...

Sheet List
A1: # | B1: Duration | C1: Term | D1: Profit | E1: Income | F1: Investment | G1: Count | H1: Days | J1: Seed | K1: Recovery | L1: %
A2: 1 | B2: ='Term-1'!$B$1 -> May2023 - Sept2023 | C2: Term-1 | D2: =IF(F2="","",E2-F2) -> -790524 | E2: ='Term-1'!$M$2 -> 1260400 | F2: ='Term-1'!$E$2 -> 2050924 | G2: =MIN('Term-1'!H5:H11) -> 80 | H2: {='Term-1'!H2:I2} -> 75 days | I2: 0 | J2: ='Term-1'!$F$31 -> 700000 | K2: ='Term-1'!$F$40 -> 424400 | L2: ='Term-1'!$F$41 -> 60.63%
A3: 2 | B3: ='Term-2'!$B$1 -> Sept2023 - Nov2023 | C3: Term-2 | D3: =IF(F3="","",E3-F3) -> -218110 | E3: ='Term-2'!$M$2 -> 300000 | F3: ='Term-2'!$E$2 -> 518110 | G3: =MIN('Term-2'!H5:H11) -> 325 | H3: {='Term-2'!H2:I2} -> 27 days | I3: 0 | J3: ='Term-2'!$F$31 -> 800000 | K3: ='Term-2'!$F$40 -> 620000 | L3: ='Term-2'!$F$41 -> 77.5%
A4: 3 | B4: ='Term-3'!$B$1 -> Nov2023 - Jan2024 | C4: Term-3 | D4: =IF(F4="","",E4-F4) -> -470000 | E4: ='Term-3'!$M$2 -> 120000 | F4: ='Term-3'!$E$2 -> 590000 | G4: =MIN('Term-3'!H5:H11) -> 325 | H4: {='Term-3'!H2:I2} -> 37 days | I4: 0 | J4: ='Term-3'!$F$31 -> 700000 | K4: ='Term-3'!$F$40 -> 390000 | L4: ='Term-3'!$F$41 -> 55.71%
A5: 4 | B5: ='Term-4'!$B$1 -> Feb2024 - May2024 | C5: Term-4 | D5: =IF(F5="","",E5-F5) -> 1098545 | E5: ='Term-4'!$M$2 -> 2700044 | F5: ='Term-4'!$E$2 -> 1601499 | G5: =MIN('Term-4'!H5:H11) -> 62 | H5: {='Term-4'!H2:I2} -> 72 days | I5: 0 | J5: ='Term-4'!$F$31 -> 700000 | K5: ='Term-4'!$F$40 -> 807868 | L5: ='Term-4'!$F$41 -> 115.41%
A6: 5 | B6: ='Term-5'!$B$1 -> July 2024 - Sept2024 | C6: Term-5 | D6: =IF(F6="","",E6-F6) -> 391120 | E6: ='Term-5'!$M$2 -> 1612322 | F6: ='Term-5'!$E$2 -> 1221202 | G6: =MIN('Term-5'!H5:H11) -> 110 | H6: {='Term-5'!H2:I2} -> 58 days | I6: 0 | J6: ='Term-5'!$F$31 -> 750000 | K6: ='Term-5'!$F$40 -> 696542.2 | L6: ='Term-5'!$F$41 -> 92.87%
A7: 6 | B7: ='Term-6'!$B$1 -> Sep2024 - Nov2024 | C7: Term-6 | D7: =IF(F7="","",E7-F7) -> 1002304 | E7: ='Term-6'!$M$2 -> 2415103 | F7: ='Term-6'!$E$2 -> 1412799 | G7: =MIN('Term-6'!H5:H11) -> 65 | H7: {='Term-6'!H2:I2} -> 73 days | I7: 0 | J7: ='Term-6'!$F$31 -> 700000 | K7: ='Term-6'!$F$40 -> 526058.6 | L7: ='Term-6'!$F$41 -> 75.15%
A8: 7 | B8: ='Term-7'!$B$1 -> Dec2024 - Feb2025 | C8: Term-7 | D8: =IF(F8="","",E8-F8) -> 528979 | E8: ='Term-7'!$M$2 -> 2031828 | F8: ='Term-7'!$E$2 -> 1502849 | G8: =MIN('Term-7'!H5:H11) -> 97 | H8: {='Term-7'!H2:I2} -> 79 days | I8: 0 | J8: ='Term-7'!$F$31 -> 925000 | K8: ='Term-7'!$F$40 -> 842685 | L8: ='Term-7'!$F$41 -> 91.1%
A9: 8 | B9: ='Term-8'!$B$1 -> Feb2025 - May2025 | C9: Term-8 | D9: =IF(F9="","",E9-F9) -> 405496 | E9: ='Term-8'!$M$2 -> 1791690 | F9: ='Term-8'!$E$2 -> 1386194 | G9: =MIN('Term-8'!H5:H11) -> 67 | H9: {='Term-8'!H2:I2} -> 78 days | I9: 0 | J9: ='Term-8'!$F$31 -> 850000 | K9: ='Term-8'!$F$40 -> 587290.3 | L9: ='Term-8'!$F$41 -> 69.09%
A10: 9 | B10: ='Term-9'!$B$1 -> July2025 - Sept2025 | C10: Term-9 | D10: =IF(F10="","",E10-F10) -> 1125929.5 | E10: ='Term-9'!$M$2 -> 2535929.5 | F10: ='Term-9'!$E$2 -> 1410000 | G10: =MIN('Term-9'!H5:H13) -> 78 | H10: {='Term-9'!H2:I2} -> 62 days | I10: 0 | J10: ='Term-9'!$F$31 -> 1050000 | K10: ='Term-9'!$F$40 -> 766370 | L10: ='Term-9'!$F$41 -> 72.99%
A11: 10 | B11: ='Term-10'!$B$1 -> Sept2025 - Dec2025 | C11: Term-10 | D11: =IF(F11="","",E11-F11) -> 979350 | E11: ='Term-10'!$M$2 -> 2530350 | F11: ='Term-10'!$E$2 -> 1551000 | G11: =MIN('Term-10'!H5:H13) -> 58 | H11: {='Term-10'!H2:I2} -> 78 days | I11: 0 | J11: ='Term-10'!$F$31 -> 900000 | K11: ='Term-10'!$F$40 -> 593783 | L11: ='Term-10'!$F$41 -> 65.98%
A12: 11 | B12: ='Term-11'!$B$1 -> Dec2025 - Jan2026 | C12: Term-11 | D12: =IF(F12="","",E12-F12) -> -469722.5 | E12: ='Term-11'!$M$2 -> 115277.5 | F12: ='Term-11'!$E$2 -> 585000 | G12: =MIN('Term-11'!H5:H13) -> 518 | H12: {='Term-11'!H2:I2} -> 34 days | I12: 0 | J12: ='Term-11'!$F$31 -> 990000 | K12: ='Term-11'!$F$40 -> 918673 | L12: ='Term-11'!$F$41 -> 92.8%
A13: 12 | B13: ='Term-12'!$B$1 -> Feb2026 - Apr2026 | C13: Term-12 | D13: =IF(F13="","",E13-F13) -> 610376 | E13: ='Term-12'!$M$2 -> 2189276 | F13: ='Term-12'!$E$2 -> 1578900 | G13: =MIN('Term-12'!H6:H14) -> 121 | H13: {='Term-12'!H2:I2} -> 71 days | I13: 0 | J13: ='Term-12'!$F$31 -> 800000 | K13: ='Term-12'!$F$40 -> 1052129.2 | L13: ='Term-12'!$F$41 -> 131.52%
A14: 13 | B14: ='Term-13'!$B$1 -> May2026 - July2026 | C14: Term-13 | D14: =IF(F14="","",E14-F14) -> 76509.4 | E14: ='Term-13'!$M$2 -> 1516086.4 | F14: ='Term-13'!$E$2 -> 1439577 | G14: =MIN('Term-13'!H6:H14) -> 95 | H14: {='Term-13'!H2:I2} -> 69 days | I14: 0 | J14: ='Term-13'!$F$31 -> 800000 | K14: ='Term-13'!$F$40 -> 653560.6 | L14: ='Term-13'!$F$41 -> 81.7%
