Workbook

Sheet Term-1
B1: May2023 - Sept2023 | G1: Seed Date | H1: 45076 | J1: Profit | K1: =M2-E2 -> -782674
A2: =SUM(A5:A105) -> 473100 | D2: Total : | E2: =SUM(E5:E105) -> 2050924 | G2: Days | H2: 75 days | L2: Total : | M2: =SUM(M5:M54) -> 1268250
B3: Investment | G3: Growth | J3: Income
B4: # | C4: Date | D4: Item | E4: Amount | F4: Details | G4: Date | H4: Count | J4: # | K4: Date | L4: Item | M4: Amount | N4: Details
B5: 1 | C5: 45025 | D5: Bhoomi Magatha | E5: 200000 | F5: 5x80K | G5: 45126 | H5: 120 | I5: =IF(ISBLANK(G5),"",CONCATENATE("(",G5-$H$1+1," days)")) -> (51 days) | J5: 1 | K5: 45150 | L5: Pedda Cheruvu - 4000 | M5: 947000 | N5: 4K, 80 count, 225 price
B6: 2 | C6: 45027 | D6: JCP charges | E6: 13000 | G6: 45133 | H6: 108 | I6: =IF(ISBLANK(G6),"",CONCATENATE("(",G6-$H$1+1," days)")) -> (58 days) | J6: 2 | K6: 45173 | L6: Chinna Cheruvu - 1.2 | M6: 321250 | N6: 1285kg
B7: 3 | C7: 45029 | D7: Penta-tractor Labor | E7: 4200 | F7: 6 trips x 700 | G7: 45140 | H7: 92 | I7: =IF(ISBLANK(G7),"",CONCATENATE("(",G7-$H$1+1," days)")) -> (65 days) | J7: 3
B8: 4 | C8: 45029 | D8: Kalupu Mandu | E8: 500 | G8: 45150 | H8: 80 | I8: =IF(ISBLANK(G8),"",CONCATENATE("(",G8-$H$1+1," days)")) -> (75 days) | J8: 4
B9: 5 | C9: 45029 | D9: JCP Driver Bojanalu | E9: 701 | J9: 5
B10: 6 | C10: 45029 | D10: Penta Owner Charges | E10: 3000 | F10: 6 trip x500 | J10: 6
B11: 7 | C11: 45029 | D11: SubMercible Motors | E11: 64000 | F11: 2 motors | J11: 7
B12: 8 | C12: 45029 | D12: 4 inch Pipes & Bore | E12: 11000 | F12: 2 pipes and bore charge | G12: Chinna Cheruvu | J12: 8
B13: 9 | C13: 45029 | D13: Bore Labor Charges | E13: 19000 | F13: 3 x 3 | G13: Seed Date | H13: 45114 | J13: 9
B14: 10 | C14: 45029 | D14: Pipe from Mogallu | E14: 400 | F14: 5 feet | G14: Days | H14: 59 Days | J14: 10
B15: 11 | C15: 45029 | D15: MonoBlock Motors | E15: 47000 | F15: 2 motors and Kirayi | G15: Growth | J15: 11
B16: 12 | C16: 45029 | D16: Saman from Korukollu | E16: 801 | G16: Date | H16: Count | J16: 12
B17: 13 | C17: 45029 | D17: Samanu from Bhimavam | E17: 1500 | F17: Rangachari | G17: 45163 | H17: 115 | I17: =IF(ISBLANK(G17),"",CONCATENATE("(",G17-$H$13+1," days)")) -> (50 days) | J17: 13
B18: 14 | C18: 45029 | D18: Saman from Mogallu | E18: 2501 | F18: 1 pipe,checkwall atta, cuppling | G18: 45169 | H18: 105 | I18: =IF(ISBLANK(G18),"",CONCATENATE("(",G18-$H$13+1," days)")) -> (56 days) | J18: 14
B19: 15 | C19: 45029 | D19: Tractor Blade Work, Dammu | E19: 10000 | G19: 45171 | H19: 100 | I19: =IF(ISBLANK(G19),"",CONCATENATE("(",G19-$H$13+1," days)")) -> (58 days) | J19: 15
B20: 16 | C20: 45055 | D20: Gedalu | E20: 2500 | F20: 5 kattalu | G20: 45173 | H20: 87 | I20: =IF(ISBLANK(G20),"",CONCATENATE("(",G20-$H$13+1," days)")) -> (60 days) | J20: 16
B21: 17 | C21: 45056 | D21: Change Over Board Saman | E21: 23500 | F21: Electric saman & Plywood from Nouduru | J21: 17
B22: 18 | C22: 45057 | D22: Bolts and Nuttulu | E22: 300 | I22: =IF(ISBLANK(G22),"",CONCATENATE("(",G22-$H$13+1," days)")) | J22: 18
B23: 19 | C23: 45062 | D23: Leggalu Work | E23: 1300 | F23: Bhimavaram | J23: 19
B24: 20 | C24: 45062 | D24: Davadlu | E24: 700 | F24: Mogallu-20x35 | J24: 20
B25: 21 | C25: 45064 | D25: Pipes,Gedalu,Naram Wire, Gare Oil | E25: 10400 | F25: Nouduru-Saman and Kirayi | J25: 21
B26: 22 | C26: 45065 | D26: New Fan Sets (6) | E26: 198000 | F26: 6x33000 | J26: 22
B27: 23 | C27: 45065 | D27: Fan Set Wire | E27: 7840 | F27: 80x98 | J27: 23
B28: 24 | C28: 45065 | D28: Starters | E28: 11340 | F28: 6x1890 | J28: 24
B29: 25 | C29: 45065 | D29: Gare Oil | E29: 4000 | J29: 25
B30: 26 | C30: 45066 | D30: Pipes for New fans | E30: 8640 | F30: 24*360 | J30: 26
B31: 27 | C31: 45066 | D31: Feed Tray | E31: 800 | J31: 27
B32: 28 | C32: 45066 | D32: Auto Kirayi | E32: 360 | J32: 28
B33: 29 | C33: 45066 | D33: Kirayi - Bvrm and Noudur | E33: 1500 | J33: 29
B34: 30 | C34: 45069 | D34: Pipes from Mogallu | E34: 1600 | J34: 30
B35: 31 | C35: 45069 | D35: Bore Work | F35: To be updated | J35: 31
B36: 32 | C36: 45070 | D36: Bleaching | E36: 3000 | J36: 32
B37: 33 | C37: 45071 | D37: Fan set Saman | E37: 14500 | F37: Nouduru-Saman and Pipes | J37: 33
B38: 34 | C38: 45073 | D38: Minarals | E38: 5200 | F38: 4x1350 | J38: 34
B39: 35 | C39: 45073 | D39: Bellam, | E39: 200 | F39: 4x50 | J39: 35
B40: 36 | C40: 45074 | D40: Seed | E40: 150000 | F40: 5 Lakhs | J40: 36
...

Sheet Term-2
B1: Sept2023 - Nov2023 | G1: Seed Date | H1: 45163 | J1: Profit | K1: =M2-E2 -> -218110
A2: =SUM(A5:A104) -> 430300 | D2: Total : | E2: =SUM(E5:E104) -> 518110 | G2: Days | H2: 50 days | L2: Total : | M2: =SUM(M5:M54) -> 300000
B3: Investment | G3: Growth | J3: Income
B4: # | C4: Date | D4: Item | E4: Amount | F4: Details | G4: Date | H4: Count | J4: # | K4: Date | L4: Item | M4: Amount | N4: Details
B5: 1 | C5: 45163 | D5: Seed | E5: 180000 | F5: 6Lx0.30 | G5: 45189 | H5: 325 | I5: =IF(ISBLANK(G5),"",CONCATENATE("(",G5-$H$1+1," days)")) -> (27 days) | J5: 1 | K5: 45189 | L5: Total | M5: 300000
B6: 2 | C6: 45163 | D6: Seed Kirayi | E6: 10000 | I6: =IF(ISBLANK(G6),"",CONCATENATE("(",G6-$H$1+1," days)")) | J6: 2
B7: 3 | C7: 45167 | D7: Metha | I7: =IF(ISBLANK(G7),"",CONCATENATE("(",G7-$H$1+1," days)")) | J7: 3
B8: 4 | C8: 45181 | D8: CurrentBill | E8: 28110 | I8: =IF(ISBLANK(G8),"",CONCATENATE("(",G8-$H$1+1," days)")) | J8: 4
B9: 5 | D9: Feed | E9: 300000 | I9: =IF(ISBLANK(G9),"",CONCATENATE("(",G9-$H$1+1," days)")) | J9: 5
B10: 6 | I10: =IF(ISBLANK(G10),"",CONCATENATE("(",G10-$H$1+1," days)")) | J10: 6
B11: 7 | J11: 7
B12: 8 | G12: Chinna Cheruvu | J12: 8
B13: 9 | G13: Seed Date | H13: 45163 | J13: 9
B14: 10 | G14: Days | H14: 50 days | J14: 10
B15: 11 | G15: Growth | J15: 11
B16: 12 | G16: Date | H16: Count | J16: 12
B17: 13 | G17: 45189 | H17: 325 | I17: =IF(ISBLANK(G17),"",CONCATENATE("(",G17-$H$13+1," days)")) -> (27 days) | J17: 13
B18: 14 | I18: =IF(ISBLANK(G18),"",CONCATENATE("(",G18-$H$13+1," days)")) | J18: 14
B19: 15 | I19: =IF(ISBLANK(G19),"",CONCATENATE("(",G19-$H$13+1," days)")) | J19: 15
B20: 16 | I20: =IF(ISBLANK(G20),"",CONCATENATE("(",G20-$H$13+1," days)")) | J20: 16
B21: 17 | I21: =IF(ISBLANK(G21),"",CONCATENATE("(",G21-$H$13+1," days)")) | J21: 17
B22: 18 | J22: 18
B23: 19 | J23: 19
B24: 20 | J24: 20
B25: 21 | J25: 21
B26: 22 | J26: 22
B27: 23 | J27: 23
B28: 24 | J28: 24
B29: 25 | J29: 25
B30: 26 | J30: 26
B31: 27 | J31: 27
B32: 28 | J32: 28
B33: 29 | J33: 29
... B54: 50 | J54: 50
B55: 51
B56: 52
B57: 53
B58: 54
B59: 55
A60: 42800 | B60: 56
...

Sheet Term-3
B1: Nov2023 - Jan2024 | G1: Seed Date | H1: 45163 | J1: Profit | K1: =M2-E2 -> -470000
A2: =SUM(A5:A104) -> 430300 | D2: Total : | E2: =SUM(E5:E104) -> 590000 | G2: Days | H2: 61 days | L2: Total : | M2: =SUM(M5:M54) -> 120000
B3: Investment | G3: Growth | J3: Income
B4: # | C4: Date | D4: Item | E4: Amount | F4: Details | G4: Date | H4: Count | J4: # | K4: Date | L4: Item | M4: Amount | N4: Details
B5: 1 | C5: 45163 | D5: Seed | E5: 180000 | F5: 6Lx0.30 | G5: 45189 | H5: 325 | I5: =IF(ISBLANK(G5),"",CONCATENATE("(",G5-$H$1+1," days)")) -> (27 days) | J5: 1 | K5: 45189 | L5: total | M5: 120000
B6: 2 | C6: 45163 | D6: Seed Kirayi | E6: 10000 | I6: =IF(ISBLANK(G6),"",CONCATENATE("(",G6-$H$1+1," days)")) | J6: 2
B7: 3 | C7: 45167 | D7: Metha | E7: 300000 | I7: =IF(ISBLANK(G7),"",CONCATENATE("(",G7-$H$1+1," days)")) | J7: 3
B8: 4 | D8: Others | E8: 100000 | I8: =IF(ISBLANK(G8),"",CONCATENATE("(",G8-$H$1+1," days)")) | J8: 4
B9: 5 | I9: =IF(ISBLANK(G9),"",CONCATENATE("(",G9-$H$1+1," days)")) | J9: 5
B10: 6 | I10: =IF(ISBLANK(G10),"",CONCATENATE("(",G10-$H$1+1," days)")) | J10: 6
B11: 7 | J11: 7
B12: 8 | G12: Chinna Cheruvu | J12: 8
B13: 9 | G13: Seed Date | H13: 45163 | J13: 9
B14: 10 | G14: Days | H14: 61 days | J14: 10
B15: 11 | G15: Growth | J15: 11
B16: 12 | G16: Date | H16: Count | J16: 12
B17: 13 | G17: 45189 | H17: 325 | I17: =IF(ISBLANK(G17),"",CONCATENATE("(",G17-$H$13+1," days)")) -> (27 days) | J17: 13
B18: 14 | I18: =IF(ISBLANK(G18),"",CONCATENATE("(",G18-$H$13+1," days)")) | J18: 14
B19: 15 | I19: =IF(ISBLANK(G19),"",CONCATENATE("(",G19-$H$13+1," days)")) | J19: 15
B20: 16 | I20: =IF(ISBLANK(G20),"",CONCATENATE("(",G20-$H$13+1," days)")) | J20: 16
B21: 17 | I21: =IF(ISBLANK(G21),"",CONCATENATE("(",G21-$H$13+1," days)")) | J21: 17
B22: 18 | J22: 18
B23: 19 | J23: 19
B24: 20 | J24: 20
B25: 21 | J25: 21
B26: 22 | J26: 22
B27: 23 | J27: 23
B28: 24 | J28: 24
B29: 25 | J29: 25
B30: 26 | J30: 26
B31: 27 | J31: 27
B32: 28 | J32: 28
B33: 29 | J33: 29
... B54: 50 | J54: 50
B55: 51
B56: 52
B57: 53
B58: 54
B59: 55
A60: 42800 | B60: 56
...

Sheet Term-4
B1: Feb2024 - May2024 | G1: Seed Date | H1: 45345 | J1: Profit | K1: =M2-E2 -> 1098545
A2: =SUM(A5:A26) -> 0 | D2: Total : | E2: =SUM(E5:E26) -> 1601499 | G2: Days | H2: 72 Days | L2: Total : | M2: =SUM(M5:M22) -> 2700044
B3: Investment | G3: Growth | J3: Income
B4: # | C4: Date | D4: Item | E4: Amount | F4: Details | G4: Date | H4: Count | J4: # | K4: Date | L4: Item | M4: Amount | N4: Details
B5: 1 | C5: 45344 | G5: 45396 | H5: 124 | I5: =IF(ISBLANK(G5),"",CONCATENATE("(",G5-$H$1+1," days)")) -> (52 days) | J5: 1 | K5: 45399 | L5: 1st Middle: Tones-200 Count-107 | M5: 432360
B6: 2 | D6: Feed | E6: 1015118 | G6: 45399 | H6: 107 | I6: =IF(ISBLANK(G6),"",CONCATENATE("(",G6-$H$1+1," days)")) -> (55 days) | J6: 2 | K6: 45408 | L6: 2nd Middle: Tones-230 Count-80 | M6: 454020
B7: 3 | D7: Seed & Others | E7: 436381 | F7: From Vizianagaram | G7: 45404 | H7: 88 | I7: =IF(ISBLANK(G7),"",CONCATENATE("(",G7-$H$1+1," days)")) -> (60 days) | J7: 3 | K7: 45408 | L7: Chinna Tank-937T-270 Count-60 | M7: 253179
B8: 4 | D8: Feed-30 bags | E8: 65000 | G8: 45407 | H8: 80 | I8: =IF(ISBLANK(G8),"",CONCATENATE("(",G8-$H$1+1," days)")) -> (63 days) | J8: 4 | K8: 45416 | L8: 3rd Middle: 2164 tones -250 Count-70 | M8: 535000
B9: 5 | D9: Feed | E9: 85000 | G9: 45408 | H9: 78 | I9: =IF(ISBLANK(G9),"",CONCATENATE("(",G9-$H$1+1," days)")) -> (64 days) | J9: 5 | K9: 45421 | L9: Final-3740 tones-275 count 60 | M9: 1025485
B10: 6 | G10: 45415 | H10: 62 | I10: =IF(ISBLANK(G10),"",CONCATENATE("(",G10-$H$1+1," days)")) -> (71 days) | J10: 6
B11: 7 | G11: 45416 | H11: 65 | I11: =IF(ISBLANK(G11),"",CONCATENATE("(",G11-$H$1+1," days)")) -> (72 days) | J11: 7
B12: 8 | G12: 45419 | H12: 58 | I12: =IF(ISBLANK(G12),"",CONCATENATE("(",G12-$H$1+1," days)")) -> (75 days) | J12: 8
B13: 9 | G13: 45421 | H13: 58 | I13: =IF(ISBLANK(G13),"",CONCATENATE("(",G13-$H$1+1," days)")) -> (77 days) | J13: 9
B14: 10 | G14: Small Tank Seed Date | J14: 10
B15: 11 | G15: Seed Date | H15: 45345 | J15: 11
B16: 12 | G16: Days | H16: 72 Days | J16: 12
B17: 13 | G17: Growth | J17: 13
B18: 14 | G18: Date | H18: Count | J18: 14
B19: 15 | G19: 45404 | H19: 60 | I19: =IF(ISBLANK(G19),"",CONCATENATE("(",G19-$H$15+1," days)")) -> (60 days) | J19: 15
B20: 16 | G20: 45408 | H20: 57 | I20: =IF(ISBLANK(G20),"",CONCATENATE("(",G20-$H$15+1," days)")) -> (64 days) | J20: 16
B21: 17 | I21: =IF(ISBLANK(G21),"",CONCATENATE("(",G21-$H$15+1," days)")) | J21: 17
B22: 18 | I22: =IF(ISBLANK(G22),"",CONCATENATE("(",G22-$H$15+1," days)")) | J22: 18
B23: 97
B24: 98
B25: 99
B26: 100
E27: Total Seed: | F27: 700000
E28: Trip | F28: Number | G28: Count | H28: Quantity | I28: Price | J28: Total
E29: Function | F29: =40*125 -> 5000 | G29: 124 | H29: 40 | I29: 0 | J29: =H29*I29 -> 0 | L29: 1st Middle | M29: 432360
E30: 1st Middle | F30: =2162*107 -> 231334 | G30: 107 | H30: 2161.8 | I30: 200 | J30: =H30*I30 -> 432360 | L30: Feed | M30: 500000
E31: 2nd Middle | F31: =1974*80 -> 157920 | G31: 80 | H31: 1974 | I31: 230 | J31: =H31*I31 -> 454020 | L31: Lease | M31: 200000
E32: 3rd Middle | F32: =2140*66 -> 141240 | G32: 70 | H32: 2164 | I32: 250 | J32: =H32*I32 -> 541000 | L32: Account | M32: 7000
E33: Small Tank | F33: =937*57 -> 53409 | G33: 60 | H33: 937.7 | I33: 270 | J33: =H33*I33 -> 253179 | L33: Feed | M33: 500000
E34: Final | F34: 215586 | G34: 58 | H34: 3687.6 | I34: 275 | J34: =H34*I34 -> 1014090 | L34: Cash | M34: 531845
E35: Loose Shell | F35: 1334 | G35: 58 | H35: 53 | I35: 215 | J35: =H35*I35 -> 11395 | L35: Cash | M35: 500000
E36: Total: | F36: =SUM(F29:F34) -> 804489 | H36: =SUM(H29:H35) -> 11018.1 | J36: =SUM(J29:J35) -> 2706044 | L36: Account | M36: 34000
E37: Number Found | F37: =CONCATENATE(ROUND((F36/F27)*100,2),"%") -> 114.93% | M37: =SUM(M29:M36) -> 2705205
L38: Balance | M38: =J36-M37 -> 839

Sheet Term-5
B1: July 2024 - Sept2024 | G1: Seed Date | H1: 45477 | J1: Profit | K1: =M2-E2 -> 391120
D2: Total : | E2: =SUM(E5:E30) -> 1221202 | G2: Days | H2: 58 Days | L2: Total : | M2: =SUM(M5:M22) -> 1612322
B3: Investment | G3: Growth | J3: Income
B4: # | C4: Date | D4: Item | E4: Amount | F4: Details | G4: Date | H4: Count | J4: # | K4: Date | L4: Item | M4: Amount | N4: Details
B5: 1 | C5: 45446 | D5: Cheruvu Pani | E5: 40000 | G5: 45527 | H5: 110 | I5: =IF(ISBLANK(G5),"",CONCATENATE("(",G5-$H$1+1," days)")) -> (51 days) | J5: 1 | K5: 45534 | L5: Big Tank-5389.8 kgs-249 rate - count 111 | M5: 1334590
B6: 2 | C6: 45477 | D6: Seed | E6: 262500 | F6: 1200*800 | G6: 45534 | H6: 111 | I6: =IF(ISBLANK(G6),"",CONCATENATE("(",G6-$H$1+1," days)")) -> (58 days) | J6: 2 | K6: 45543 | L6: Small Tank-1068 kg-260 rate-92 count | M6: 277732
B7: 3 | C7: 45477 | D7: Van Kirayi | E7: 12000 | I7: =IF(ISBLANK(G7),"",CONCATENATE("(",G7-$H$1+1," days)")) | J7: 3
B8: 4 | C8: 45474 | D8: Others | E8: 30000 | I8: =IF(ISBLANK(G8),"",CONCATENATE("(",G8-$H$1+1," days)")) | J8: 4
B9: 5 | C9: 45537 | D9: Mogallu Feed Shop | E9: 623857 | F9: Feed + Medicine | I9: =IF(ISBLANK(G9),"",CONCATENATE("(",G9-$H$1+1," days)")) | J9: 5
B10: 6 | C10: 45550 | D10: Aravalli Shop | E10: 133202 | I10: =IF(ISBLANK(G10),"",CONCATENATE("(",G10-$H$1+1," days)")) | J10: 6
B11: 7 | C11: 45534 | D11: Current Bill, Assam Salary etc | E11: 100000 | I11: =IF(ISBLANK(G11),"",CONCATENATE("(",G11-$H$1+1," days)")) | J11: 7
B12: 8 | C12: 45550 | D12: Mogallu Feed Shop-Extra | E12: 19643 | I12: =IF(ISBLANK(G12),"",CONCATENATE("(",G12-$H$1+1," days)")) | J12: 8
B13: 9 | D13: Surya Calculation: | I13: =IF(ISBLANK(G13),"",CONCATENATE("(",G13-$H$1+1," days)")) | J13: 9
B14: 10 | D14: 3400 | G14: Small Tank Seed Date | J14: 10
B15: 11 | D15: 20000 | G15: Seed Date | H15: 45477 | J15: 11
B16: 12 | D16: 276000 | G16: Days | H16: 67 Days | J16: 12
B17: 13 | D17: 2300 | G17: Growth | J17: 13
B18: 14 | D18: 3400 | G18: Date | H18: Count | J18: 14
B19: 15 | D19: 9100 | G19: 45527 | H19: 106 | I19: =IF(ISBLANK(G19),"",CONCATENATE("(",G19-$H$15+1," days)")) -> (51 days) | J19: 15
B20: 16 | D20: 1500 | G20: 45534 | H20: 96 | I20: =IF(ISBLANK(G20),"",CONCATENATE("(",G20-$H$15+1," days)")) -> (58 days) | J20: 16
B21: 17 | D21: 3200 | G21: 45541 | H21: 91 | I21: =IF(ISBLANK(G21),"",CONCATENATE("(",G21-$H$15+1," days)")) -> (65 days) | J21: 17
B22: 18 | D22: 12237 | G22: 45543 | H22: 92 | I22: =IF(ISBLANK(G22),"",CONCATENATE("(",G22-$H$15+1," days)")) -> (67 days) | J22: 18
B23: 19 | D23: 15500 | J23: 19
B24: 20 | D24: 3000 | J24: 20
B25: 21 | D25: 8000 | J25: 21
B26: 22 | D26: 22300 | J26: 22
B27: 23 | D27: 15000 | J27: 23
B28: 24 | D28: 6140 | J28: 24
B29: 25 | D29: 1500 | J29: 25
D30: =SUM(D14:D29) -> 402577
C31: Feed | D31: 643500 | E31: Total Seed: | F31: 750000
C32: Manchili shop | D32: 133202 | E32: Trip | F32: Number | G32: Count | H32: Quantity | I32: Price | J32: Total | L32: Cash Credits
C33: Ishan salary | D33: 30000 | E33: Big Tank - Full | F33: =H33*G33 -> 591607.8 | G33: 111 | H33: 5329.8 | I33: 249 | J33: =H33*I33 -> 1327120.2 | L33: Feed Shop | M33: 600000
D34: 1209279 | E34: Big Tank - Soft | F34: =H34*G34 -> 6660 | G34: 111 | H34: 60 | I34: 124.5 | J34: =H34*I34 -> 7470 | L34: Surya | M34: 250000
C35: Balance | D35: =J40-D34 -> 403043.2 | E35: Small Tank - Full | F35: =H35*G35 -> 98274.4 | G35: 92 | H35: 1068.2 | I35: 250 | J35: =H35*I35 -> 267050 | L35: Surya | M35: 50000
F36: =H36*G36 -> 0 | H36: 1068.2 | I36: 10 | J36: =H36*I36 -> 10682 | L36: Cash | M36: 568000
F37: =H37*G37 -> 0 | J37: =H37*I37 -> 0 | L37: Feed Shop Manchili (-) | M37: 133202
F38: =H38*G38 -> 0 | J38: =H38*I38 -> 0 | L38: Cash | M38: 10000
F39: =H39*G39 -> 0 | J39: =H39*I39 -> 0
E40: Total: | F40: =SUM(F33:F38) -> 696542.2 | H40: =SUM(H33:H39) -> 7526.2 | J40: =SUM(J33:J39) -> 1612322.2
...

Sheet Term-6
B1: Sep2024 - Nov2024 | G1: Seed Date | H1: 45548 | J1: Profit | K1: =M2-E2 -> 1002304
D2: Total : | E2: =SUM(E5:E30) -> 1412799 | G2: Days | H2: 73 Days | L2: Total : | M2: =SUM(M5:M22) -> 2415103
B3: Investment | G3: Growth | J3: Income
B4: # | C4: Date | D4: Item | E4: Amount | F4: Details | G4: Date | H4: Count | I4: Days | J4: # | K4: Date | L4: Item | M4: Amount | N4: Details
B5: 1 | C5: 45548 | D5: Seed | E5: 210000 | F5: Seed from Anjaneya, Gudur | G5: 45599 | H5: 96 | I5: =IF(ISBLANK(G5),"",CONCATENATE(G5-$H$1+1," days")) -> 52 days | J5: 1 | K5: 45609 | L5: 1st Middle: Tones-2 Rate-270 Count-80 | M5: 558927
B6: 2 | C6: 45548 | D6: Van Kirayi | E6: 30000 | G6: 45602 | H6: 91 | I6: =IF(ISBLANK(G6),"",CONCATENATE(G6-$H$1+1," days")) -> 55 days | J6: 2 | K6: 45620 | L6: Big Tank Final: Tones-4619.9 Rate-320 Count-70 | M6: 1478368
B7: 3 | C7: 45561 | D7: Small Tank Seed | E7: 35000 | F7: Seed from Anjaneya, Gudur | G7: 45606 | H7: 84 | I7: =IF(ISBLANK(G7),"",CONCATENATE(G7-$H$1+1," days")) -> 59 days | J7: 3 | K7: 45633 | L7: Small Tank:Tons-1111.2,Rate-340 count-60 | M7: 377808
B8: 4 | C8: 45561 | D8: Small Tank Seed Kirayi | E8: 3500 | G8: 45608 | H8: 81 | I8: =IF(ISBLANK(G8),"",CONCATENATE(G8-$H$1+1," days")) -> 61 days | J8: 4
B9: 5 | C9: 45520 | D9: Current Bill | E9: 22303 | G9: 45609 | H9: 79 | I9: =IF(ISBLANK(G9),"",CONCATENATE(G9-$H$1+1," days")) -> 62 days | J9: 5
B10: 6 | C10: 45551 | D10: Current Bill | E10: 17625 | G10: 45614 | H10: 65 | I10: =IF(ISBLANK(G10),"",CONCATENATE(G10-$H$1+1," days")) -> 67 days | J10: 6
B11: 7 | C11: 45599 | D11: Danayya Vala | E11: 1200 | G11: 45619 | H11: 70 | I11: =IF(ISBLANK(G11),"",CONCATENATE(G11-$H$1+1," days")) -> 72 days | J11: 7
B12: 8 | C12: 45609 | D12: 1st middle vala payment | E12: 5600 | G12: 45620 | H12: 65 | I12: =IF(ISBLANK(G12),"",CONCATENATE(G12-$H$1+1," days")) -> 73 days | J12: 8
B13: 9 | C13: 45620 | D13: 10 tons feed so far | E13: 893146 | I13: =IF(ISBLANK(G13),"",CONCATENATE(G13-$H$1+1," days")) | J13: 9
B14: 10 | C14: 45620 | D14: Big Tank Vala payment | E14: 17400 | G14: Small Tank | J14: 10
B15: 11 | C15: 45581 | D15: Current Bill | E15: 22755 | G15: Seed Date | H15: 45561 | J15: 11
B16: 12 | C16: 45634 | D16: Small Tank Feed | E16: 27000 | G16: Days | H16: 73 Days | J16: 12
B17: 13 | C17: 45634 | D17: Ishan Salary | E17: 45000 | G17: Growth | J17: 13
B18: 14 | C18: 45644 | D18: Medicine | E18: 82270 | G18: Date | H18: Count | I18: Days | J18: 14
B19: 15 | G19: 45602 | H19: 130 | I19: =IF(ISBLANK(G19),"",CONCATENATE(G19-$H$15+1," days")) -> 42 days | J19: 15
B20: 16 | G20: 45608 | H20: 99 | I20: =IF(ISBLANK(G20),"",CONCATENATE(G20-$H$15+1," days")) -> 48 days | J20: 16
B21: 17 | G21: 45614 | H21: 80 | I21: =IF(ISBLANK(G21),"",CONCATENATE(G21-$H$15+1," days")) -> 54 days | J21: 17
B22: 18 | G22: 45619 | H22: 71 | I22: =IF(ISBLANK(G22),"",CONCATENATE(G22-$H$15+1," days")) -> 59 days | J22: 18
B23: 19 | G23: 45624 | H23: 61 | I23: =IF(ISBLANK(G23),"",CONCATENATE(G23-$H$15+1," days")) -> 64 days | J23: 19
B24: 20 | G24: 45631 | H24: 60 | I24: =IF(ISBLANK(G24),"",CONCATENATE(G24-$H$15+1," days")) -> 71 days | J24: 20
B25: 21 | G25: 45633 | H25: 56 | I25: =IF(ISBLANK(G25),"",CONCATENATE(G25-$H$15+1," days")) -> 73 days | J25: 21
B26: 22 | I26: =IF(ISBLANK(G26),"",CONCATENATE(G26-$H$15+1," days")) | J26: 22
B27: 23 | J27: 23
B28: 24 | J28: 24
B29: 25 | J29: 25
E31: Total Seed: | F31: 700000
E32: Trip | F32: Number | G32: Count | H32: Quantity | I32: Price | J32: Total | L32: Cash Credits
E33: 1st Middle | F33: =H33*G33 -> 163537.9 | G33: 79 | H33: 2070.1 | I33: 270 | J33: =H33*I33 -> 558927 | L33: Surya Account | M33: 200000
E34: Big Tank-Final | F34: =H34*G34 -> 300293.5 | G34: 65 | H34: 4619.9 | I34: 320 | J34: =H34*I34 -> 1478368 | L34: Lease | M34: 200000
E35: Small Tank | F35: =H35*G35 -> 62227.2 | G35: 56 | H35: 1111.2 | I35: 340 | J35: =H35*I35 -> 377808 | L35: Cash | M35: 158927
F36: =H36*G36 -> 0 | J36: =H36*I36 -> 0 | L36: Feed Shop | M36: 900000
F37: =H37*G37 -> 0 | J37: =H37*I37 -> 0 | L37: Seed | M37: 200000
F38: =H38*G38 -> 0 | J38: =H38*I38 -> 0 | L38: Cash | M38: 300000
F39: =H39*G39 -> 0 | J39: =H39*I39 -> 0 | L39: Medicine | M39: 82270
L40: Cash | M40: 300000
L41: Cash | M41: 83600
...

Sheet Term-7
B1: Dec2024 - Feb2025 | G1: Seed Date | H1: 45631 | J1: Profit | K1: =M2-E2 -> 528979
D2: Total : | E2: =SUM(E5:E30) -> 1502849 | G2: Days | H2: 79 Days | L2: Total : | M2: =SUM(M5:M22) -> 2031828
B3: Investment | G3: Growth | J3: Income
B4: # | C4: Date | D4: Item | E4: Amount | F4: Details | G4: Date | H4: Count | I4: Days | J4: # | K4: Date | L4: Item | M4: Amount | N4: Details
B5: 1 | C5: 45631 | D5: Big Tank Seed | E5: 265000 | F5: From Pondichery(8L) | G5: 45692 | H5: 137 | I5: =IF(ISBLANK(G5),"",CONCATENATE(G5-$H$1+1," days")) -> 62 days | J5: 1 | K5: 45701 | L5: 1st Middle: Tones 2149.5-Rs.245 Count-110 | M5: 526628
B6: 2 | C6: 45631 | D6: Kirayi | E6: 38941 | G6: 45701 | H6: 110 | I6: =IF(ISBLANK(G6),"",CONCATENATE(G6-$H$1+1," days")) -> 71 days | J6: 2 | K6: 45709 | L6: Big Tank-Final-5220T-260R-100C | M6: 1357200
B7: 3 | C7: 45677 | D7: Current Bill | E7: 23950 | G7: 45708 | H7: 100 | I7: =IF(ISBLANK(G7),"",CONCATENATE(G7-$H$1+1," days")) -> 78 days | J7: 3 | K7: 45717 | L7: Small Tank-600Q-200R-135C | M7: 148000
B8: 4 | C8: 45653 | D8: Small Tank Seed | E8: 40000 | F8: From Kakinada(1.25L) | G8: 45709 | H8: 97 | I8: =IF(ISBLANK(G8),"",CONCATENATE(G8-$H$1+1," days")) -> 79 days | J8: 4
B9: 5 | C9: 45701 | D9: Middle Expenses | E9: 8000 | I9: =IF(ISBLANK(G9),"",CONCATENATE(G9-$H$1+1," days")) | J9: 5
B10: 6 | C10: 45705 | D10: Current Bill | E10: 31958 | I10: =IF(ISBLANK(G10),"",CONCATENATE(G10-$H$1+1," days")) | J10: 6
B11: 7 | C11: 45714 | D11: Feed | E11: 1095000 | I11: =IF(ISBLANK(G11),"",CONCATENATE(G11-$H$1+1," days")) | J11: 7
B12: 8 | I12: =IF(ISBLANK(G12),"",CONCATENATE(G12-$H$1+1," days")) | J12: 8
B13: 9 | I13: =IF(ISBLANK(G13),"",CONCATENATE(G13-$H$1+1," days")) | J13: 9
B14: 10 | G14: Small Tank | J14: 10
B15: 11 | G15: Seed Date | H15: 45653 | J15: 11
B16: 12 | G16: Days | H16: 65 Days | J16: 12
B17: 13 | G17: Growth | J17: 13
B18: 14 | G18: Date | H18: Count | I18: Days | J18: 14
B19: 15 | G19: 45692 | H19: 240 | I19: =IF(ISBLANK(G19),"",CONCATENATE(G19-$H$15+1," days")) -> 40 days | J19: 15
B20: 16 | G20: 45700 | H20: 186 | I20: =IF(ISBLANK(G20),"",CONCATENATE(G20-$H$15+1," days")) -> 48 days | J20: 16
B21: 17 | G21: 45708 | H21: 142 | I21: =IF(ISBLANK(G21),"",CONCATENATE(G21-$H$15+1," days")) -> 56 days | J21: 17
B22: 18 | G22: 45714 | H22: 146 | I22: =IF(ISBLANK(G22),"",CONCATENATE(G22-$H$15+1," days")) -> 62 days | J22: 18
B23: 19 | G23: 45717 | H23: 140 | I23: =IF(ISBLANK(G23),"",CONCATENATE(G23-$H$15+1," days")) -> 65 days | J23: 19
B24: 20 | I24: =IF(ISBLANK(G24),"",CONCATENATE(G24-$H$15+1," days")) | J24: 20
B25: 21 | I25: =IF(ISBLANK(G25),"",CONCATENATE(G25-$H$15+1," days")) | J25: 21
B26: 22 | J26: 22
B27: 23 | J27: 23
B28: 24 | J28: 24
B29: 25 | J29: 25
E31: Total Seed: | F31: 925000
E32: Trip | F32: Number | G32: Count | H32: Quantity | I32: Price | J32: Total | L32: Cash Credits
E33: 1st Middle | F33: =H33*G33 -> 236445 | G33: 110 | H33: 2149.5 | I33: 245 | J33: =H33*I33 -> 526627.5 | L33: Surya Account | M33: 200000
E34: Big Tank-Final | F34: =H34*G34 -> 506340 | G34: 97 | H34: 5220 | I34: 260 | J34: =H34*I34 -> 1357200 | L34: Surya Account | M34: 50000
E35: Small Tank | F35: =H35*G35 -> 99900 | G35: 135 | H35: 740 | I35: 200 | J35: =H35*I35 -> 148000 | L35: Surya Account | M35: 200000
F36: =H36*G36 -> 0 | J36: =H36*I36 -> 0 | L36: Feed | M36: 1095000
F37: =H37*G37 -> 0 | J37: =H37*I37 -> 0 | L37: Seed | M37: 240000
F38: =H38*G38 -> 0 | J38: =H38*I38 -> 0 | L38: Cash | M38: 274600
F39: =H39*G39 -> 0 | J39: =H39*I39 -> 0
E40: Total: | F40: =SUM(F33:F38) -> 842685 | H40: =SUM(H33:H39) -> 8109.5 | J40: =SUM(J33:J39) -> 2031827.5 | L40: Total: | M40: =SUM(M33:M39) -> 2059600
E41: Number Found | F41: =CONCATENATE(ROUND((F40/F31)*100,2),"%") -> 91.1% | L41: Balance: | M41: =J40-M40 -> -27772.5
...

Sheet Term-8
B1: Feb2025 - May2025 | G1: Seed Date | H1: 45714 | J1: Profit | K1: =M2-E2 -> 405496
D2: Total : | E2: =SUM(E5:E30) -> 1386194 | G2: Days | H2: 78 Days | L2: Total : | M2: =SUM(M5:M22) -> 1791690
B3: Investment | G3: Growth | J3: Income
B4: # | C4: Date | D4: Item | E4: Amount | F4: Details | G4: Date | H4: Count | I4: Days | J4: # | K4: Date | L4: Item | M4: Amount | N4: Details
B5: 1 | C5: 45714 | D5: Seed for Big Tank | E5: 257500 | F5: 750000 - From Gudur | G5: 45765 | H5: 157 | I5: =IF(ISBLANK(G5),"",CONCATENATE(G5-$H$1+1," days")) -> 52 days | J5: 1 | K5: 45775 | L5: 1st Middle - 110C-220R-1674T | M5: 368280
B6: 2 | C6: 45743 | D6: Seed for Small Tank | E6: 35000 | F6: 100000 - From Gudur | G6: 45775 | H6: 110 | I6: =IF(ISBLANK(G6),"",CONCATENATE(G6-$H$1+1," days")) -> 62 days | J6: 2 | K6: 45787 | L6: 2nd Middle - 73C-265R-2194.4T | M6: 571064
B7: 3 | C7: 45792 | D7: 10.5 tons feed so far | E7: 984721 | G7: 45783 | H7: 86 | I7: =IF(ISBLANK(G7),"",CONCATENATE(G7-$H$1+1," days")) -> 70 days | J7: 3 | K7: 45791 | L7: Big Tank - Final - 67C-280R-2425T | M7: 679140
B8: 4 | C8: 45792 | D8: Cash Investment | E8: 108973 | G8: 45787 | H8: 74 | I8: =IF(ISBLANK(G8),"",CONCATENATE(G8-$H$1+1," days")) -> 74 days | J8: 4 | K8: 45791 | L8: Small Tank - Final-100C-220R-787Q | M8: 173206
B9: 5 | G9: 45791 | H9: 67 | I9: =IF(ISBLANK(G9),"",CONCATENATE(G9-$H$1+1," days")) -> 78 days | J9: 5
B10: 6 | D10: 900 | I10: =IF(ISBLANK(G10),"",CONCATENATE(G10-$H$1+1," days")) | J10: 6
B11: 7 | D11: 2400 | I11: =IF(ISBLANK(G11),"",CONCATENATE(G11-$H$1+1," days")) | J11: 7
B12: 8 | D12: 25261 | I12: =IF(ISBLANK(G12),"",CONCATENATE(G12-$H$1+1," days")) | J12: 8
B13: 9 | D13: 3360 | I13: =IF(ISBLANK(G13),"",CONCATENATE(G13-$H$1+1," days")) | J13: 9
B14: 10 | D14: 6000 | G14: Small Tank | J14: 10
B15: 11 | D15: 6000 | G15: Seed Date | H15: 45743 | J15: 11
B16: 12 | D16: 4956 | G16: Days | H16: 48 Days | J16: 12
B17: 13 | D17: 5600 | G17: Growth | J17: 13
B18: 14 | D18: 3000 | G18: Date | H18: Count | I18: Days | J18: 14
B19: 15 | D19: 26577 | G19: 45783 | H19: 132 | I19: =IF(ISBLANK(G19),"",CONCATENATE(G19-$H$15+1," days")) -> 41 days | J19: 15
B20: 16 | D20: 24919 | G20: 45791 | H20: 102 | I20: =IF(ISBLANK(G20),"",CONCATENATE(G20-$H$15+1," days")) -> 49 days | J20: 16
B21: 17 | I21: =IF(ISBLANK(G21),"",CONCATENATE(G21-$H$15+1," days")) | J21: 17
B22: 18 | I22: =IF(ISBLANK(G22),"",CONCATENATE(G22-$H$15+1," days")) | J22: 18
B23: 19 | I23: =IF(ISBLANK(G23),"",CONCATENATE(G23-$H$15+1," days")) | J23: 19
B24: 20 | I24: =IF(ISBLANK(G24),"",CONCATENATE(G24-$H$15+1," days")) | J24: 20
B25: 21 | I25: =IF(ISBLANK(G25),"",CONCATENATE(G25-$H$15+1," days")) | J25: 21
B26: 22 | J26: 22
B27: 23 | J27: 23
B28: 24 | J28: 24
B29: 25 | J29: 25
E31: Total Seed: | F31: 850000
E32: Trip | F32: Number | G32: Count | H32: Quantity | I32: Price | J32: Total | L32: Cash Credits
E33: 1st Middle | F33: =H33*G33 -> 184140 | G33: 110 | H33: 1674 | I33: 220 | J33: =H33*I33 -> 368280 | L33: Reddy Garu - Advance | M33: 400000
E34: 2nd Middle | F34: =H34*G34 -> 160337.2 | G34: 73 | H34: 2196.4 | I34: 260 | J34: =H34*I34 -> 571064 | L34: Surya Account - 24/05/2025 | M34: 200000
E35: Big Tank - Final | F35: =H35*G35 -> 162508.5 | G35: 67 | H35: 2425.5 | I35: 280 | J35: =H35*I35 -> 679140 | L35: Liquid Cash - 27/05/2025 | M35: 250000
E36: Small Tank | F36: =H36*G36 -> 80304.6 | G36: 102 | H36: 787.3 | I36: 220 | J36: =H36*I36 -> 173206 | L36: Feed - 10.5 Tons | M36: 985721
F37: 0 | J37: =H37*I37 -> 0
F38: =H38*G38 -> 0 | J38: =H38*I38 -> 0
F39: =H39*G39 -> 0 | J39: =H39*I39 -> 0
E40: Total: | F40: =SUM(F33:F38) -> 587290.3 | H40: =SUM(H33:H39) -> 7083.2 | J40: =SUM(J33:J39) -> 1791690 | L40: Total: | M40: =SUM(M33:M39) -> 1835721
E41: Number Found | F41: =CONCATENATE(ROUND((F40/F31)*100,2),"%") -> 69.09% | L41: Balance: | M41: =J40-M40 -> -44031
...

Sheet Term-9
A1: July2025 - Sept2025 | F1: Seed Date | G1: 45840 | I1: Profit | J1: =L2-D2 -> 1125929.5
C2: Total : | D2: =SUM(D5:D30) -> 1410000 | F2: Days | G2: 62 Days | K2: Total : | L2: =SUM(L5:L22) -> 2535929.5
A3: Investment | F3: Growth | I3: Income
A4: # | B4: Date | C4: Item | D4: Amount | E4: Details | F4: Date | G4: Count | H4: Days | I4: # | J4: Date | K4: Item | L4: Amount | M4: Details
A5: 1 | B5: 45840 | C5: Seed for Big Tank | D5: 300000 | E5: 1068 packets from Kakinada | F5: 45884 | G5: 135 | H5: =IF(ISBLANK(F5),"",CONCATENATE(F5-$G$1+1," days")) -> 45 days | I5: 1 | J5: 45893 | K5: 1st Middle - 100C-245R-2171T | L5: 521040
A6: 2 | C6: Cash Investment | D6: 160000 | F6: 45889 | G6: 120 | H6: =IF(ISBLANK(F6),"",CONCATENATE(F6-$G$1+1," days")) -> 50 days | I6: 2 | J6: 45900 | K6: 2nd Middle - 80C-265R-2854.7T | L6: 756496
A7: 3 | C7: Feed so far 10 tones | D7: 920000 | F7: 45893 | G7: 98 | H7: =IF(ISBLANK(F7),"",CONCATENATE(F7-$G$1+1," days")) -> 54 days | I7: 3 | J7: 45901 | K7: Big Tank-Final - 80C-265R-3548.7T | L7: 940405.5 | M7: Virus
A8: 4 | C8: Assam Salary | D8: 30000 | F8: 45899 | G8: 78 | H8: =IF(ISBLANK(F8),"",CONCATENATE(F8-$G$1+1," days")) -> 60 days | I8: 4 | J8: 45912 | K8: Small Tank-Final-50C-330R-900K | L8: 317988
A9: 5 | F9: 45900 | G9: 81 | H9: =IF(ISBLANK(F9),"",CONCATENATE(F9-$G$1+1," days")) -> 61 days | I9: 5
A10: 6 | F10: 45901 | G10: 79 | H10: =IF(ISBLANK(F10),"",CONCATENATE(F10-$G$1+1," days")) -> 62 days | I10: 6
A11: 7 | H11: =IF(ISBLANK(F11),"",CONCATENATE(F11-$G$1+1," days")) | I11: 7
A12: 8 | H12: =IF(ISBLANK(F12),"",CONCATENATE(F12-$G$1+1," days")) | I12: 8
A13: 9 | H13: =IF(ISBLANK(F13),"",CONCATENATE(F13-$G$1+1," days")) | I13: 9
A14: 10 | F14: Small Tank | I14: 10
A15: 11 | F15: Seed Date | G15: 45840 | I15: 11
A16: 12 | F16: Days | G16: 73 days | I16: 12
A17: 13 | F17: Growth | I17: 13
A18: 14 | F18: Date | G18: Count | H18: Days | I18: 14
A19: 15 | F19: 45884 | G19: 150 | H19: =IF(ISBLANK(F19),"",CONCATENATE(F19-$G$15+1," days")) -> 45 days | I19: 15
A20: 16 | F20: 45889 | G20: 120 | H20: =IF(ISBLANK(F20),"",CONCATENATE(F20-$G$15+1," days")) -> 50 days | I20: 16
A21: 17 | F21: 45893 | G21: 97 | H21: =IF(ISBLANK(F21),"",CONCATENATE(F21-$G$15+1," days")) -> 54 days | I21: 17
A22: 18 | F22: 45899 | G22: 80 | H22: =IF(ISBLANK(F22),"",CONCATENATE(F22-$G$15+1," days")) -> 60 days | I22: 18
A23: 19 | F23: 45900 | G23: 74 | H23: =IF(ISBLANK(F23),"",CONCATENATE(F23-$G$15+1," days")) -> 61 days | I23: 19
A24: 20 | F24: 45907 | G24: 56 | H24: =IF(ISBLANK(F24),"",CONCATENATE(F24-$G$15+1," days")) -> 68 days | I24: 20
A25: 21 | F25: 45910 | G25: 50 | H25: =IF(ISBLANK(F25),"",CONCATENATE(F25-$G$15+1," days")) -> 71 days | I25: 21
A26: 22 | F26: 45912 | G26: 48 | H26: =IF(ISBLANK(F26),"",CONCATENATE(F26-$G$15+1," days")) -> 73 days | I26: 22
A27: 23 | I27: 23
A28: 24 | I28: 24
A29: 25 | I29: 25
D31: Total Seed: | E31: 1050000 | F31: Big Tank: | G31: 900000 | H31: Small Tank: | I31: 150000
D32: Trip | E32: Number | F32: Count | G32: Quantity | H32: Price | I32: Total | K32: Cash Credits
D33: 1st Middle - Big Tank | E33: =G33*F33 -> 190815.8 | F33: 98 | G33: 1947.1 | H33: 240 | I33: =G33*H33 -> 467304 | K33: Surya Account - 02-09-2025 | L33: 100000
D34: 1st Middle - Small Tank | E34: =G34*F34 -> 21718.3 | F34: 97 | G34: 223.9 | H34: 240 | I34: =G34*H34 -> 53736 | K34: Cash - 06-09-2025 | L34: 600000
D35: 2nd Middle - Big Tank | E35: =G35*F35 -> 185004 | F35: 81 | G35: 2284 | H35: 265 | I35: =G35*H35 -> 605260 | K35: Cash - 13-09-2025 | L35: 700000
D36: 2nd Middle - Small Tank | E36: =G36*F36 -> 42231.8 | F36: 74 | G36: 570.7 | H36: 265 | I36: =G36*H36 -> 151235.5 | K36: Feed | L36: 920000
D37: Final - Big Tank | E37: =G37*F37 -> 280347.3 | F37: 79 | G37: 3548.7 | H37: 265 | I37: =G37*H37 -> 940405.5 | K37: Bend shape 6% | L37: 16000
D38: Final - Small Tank | E38: =G38*F38 -> 46252.8 | F38: 48 | G38: 963.6 | H38: 330 | I38: =G38*H38 -> 317988 | K38: Seed - 17-09-2025 | L38: 200000
E39: =G39*F39 -> 0 | I39: =G39*H39 -> 0
D40: Total: | E40: =SUM(E33:E38) -> 766370 | G40: =SUM(G33:G39) -> 9538 | I40: =SUM(I33:I39) -> 2535929 | K40: Total: | L40: =SUM(L33:L39) -> 2536000
D41: Number Found | E41: =CONCATENATE(ROUND((E40/E31)*100,2),"%") -> 72.99% | K41: Balance: | L41: =I40-L40 -> -71
...

Sheet Term-10
A1: Sept2025 - Dec2025 | F1: Seed Date | G1: 45918 | I1: Profit | J1: =L2-D2 -> 979350
C2: Total : | D2: =SUM(D5:D30) -> 1551000 | F2: Days | G2: 78 Days | K2: Total : | L2: =SUM(L5:L22) -> 2530350
A3: Investment | F3: Growth | I3: Income
A4: # | B4: Date | C4: Item | D4: Amount | E4: Details | F4: Date | G4: Count | H4: Days | I4: # | J4: Date | K4: Item | L4: Amount | M4: Details
A5: 1 | B5: 45918 | C5: Seed | D5: 288000 | E5: 9L seed from Gudur | F5: 45972 | G5: 90 | H5: =IF(ISBLANK(F5),"",CONCATENATE(F5-$G$1+1," days")) -> 55 days | I5: 1 | J5: 45975 | K5: Big Tank-1st Middle - 90C-240R-2000T | L5: 496056
A6: 2 | B6: 45918 | C6: Seed Transport | D6: 17500 | F6: 45974 | G6: 93 | H6: =IF(ISBLANK(F6),"",CONCATENATE(F6-$G$1+1," days")) -> 57 days | I6: 2 | J6: 45985 | K6: Big Tank-2nd Middle - 70C-300R-2000T | L6: 644160
A7: 3 | B7: 45961 | C7: Feed - 12 Tons so far | D7: 996000 | F7: 45975 | G7: 88 | H7: =IF(ISBLANK(F7),"",CONCATENATE(F7-$G$1+1," days")) -> 58 days | I7: 3 | J7: 45995 | K7: Big Tank-Final - 60C-335R-3392.8T | L7: 1136588
A8: 4 | B8: 45956 | C8: Diesel | D8: 15000 | F8: 45982 | G8: 72 | H8: =IF(ISBLANK(F8),"",CONCATENATE(F8-$G$1+1," days")) -> 65 days | I8: 4 | J8: 45995 | K8: Small Tank-Final-80C-265R-857.1K | L8: 244273.5
A9: 5 | B9: 45995 | C9: Extra Medicine | D9: 100000 | F9: 45985 | G9: 68 | H9: =IF(ISBLANK(F9),"",CONCATENATE(F9-$G$1+1," days")) -> 68 days | I9: 5 | J9: 46001 | K9: Big Tank - Extra | L9: 3182.5
A10: 6 | B10: 45995 | C10: Cash | D10: 70000 | F10: 45991 | G10: 62 | H10: =IF(ISBLANK(F10),"",CONCATENATE(F10-$G$1+1," days")) -> 74 days | I10: 6 | J10: 46003 | K10: Small Tank - Extra | L10: 6090
A11: 7 | B11: 45995 | C11: Current bill | D11: 34500 | F11: 45995 | G11: 58 | H11: =IF(ISBLANK(F11),"",CONCATENATE(F11-$G$1+1," days")) -> 78 days | I11: 7
A12: 8 | B12: 45995 | C12: Assam | D12: 30000 | H12: =IF(ISBLANK(F12),"",CONCATENATE(F12-$G$1+1," days")) | I12: 8
A13: 9 | H13: =IF(ISBLANK(F13),"",CONCATENATE(F13-$G$1+1," days")) | I13: 9
A14: 10 | F14: Small Tank | I14: 10
A15: 11 | F15: Seed Date | G15: 45918 | I15: 11
A16: 12 | F16: Days | G16: 78 Days | I16: 12
A17: 13 | F17: Growth | I17: 13
A18: 14 | F18: Date | G18: Count | H18: Days | I18: 14
A19: 15 | F19: 45972 | G19: 130 | H19: =IF(ISBLANK(F19),"",CONCATENATE(F19-$G$15+1," days")) -> 55 days | I19: 15
A20: 16 | F20: 45979 | G20: 110 | H20: =IF(ISBLANK(F20),"",CONCATENATE(F20-$G$15+1," days")) -> 62 days | I20: 16
A21: 17 | F21: 45991 | G21: 93 | H21: =IF(ISBLANK(F21),"",CONCATENATE(F21-$G$15+1," days")) -> 74 days | I21: 17
A22: 18 | F22: 45995 | G22: 78 | H22: =IF(ISBLANK(F22),"",CONCATENATE(F22-$G$15+1," days")) -> 78 days | I22: 18
A23: 19 | H23: =IF(ISBLANK(F23),"",CONCATENATE(F23-$G$15+1," days")) | I23: 19
A24: 20 | H24: =IF(ISBLANK(F24),"",CONCATENATE(F24-$G$15+1," days")) | I24: 20
A25: 21 | H25: =IF(ISBLANK(F25),"",CONCATENATE(F25-$G$15+1," days")) | I25: 21
A26: 22 | I26: 22
A27: 23 | I27: 23
A28: 24 | I28: 24
A29: 25 | I29: 25
D31: Total Seed: | E31: 900000 | F31: Big Tank: | G31: 750000 | H31: Small Tank: | I31: 150000
D32: Trip | E32: Number | F32: Count | G32: Quantity | H32: Price | I32: Total | K32: Cash Credits
D33: Big Tank-1st Middle | E33: =G33*F33 -> 181887.2 | F33: 88 | G33: 2066.9 | H33: 240 | I33: =G33*H33 -> 496056 | K33: Surya Account - | L33: 50000
D34: Big Tank- 2nd Middle | E34: =G34*F34 -> 146009.6 | F34: 68 | G34: 2147.2 | H34: 300 | I34: =G34*H34 -> 644160 | K34: Feed | L34: 996688
D35: Big Tank - Final | E35: =G35*F35 -> 196782.4 | F35: 58 | G35: 3392.8 | H35: 335 | I35: =G35*H35 -> 1136588 | K35: Cash - 18-12-2025 | L35: 500000
D36: Small Tank - Final | E36: =G36*F36 -> 66853.8 | F36: 78 | G36: 857.1 | H36: 285 | I36: =G36*H36 -> 244273.5 | K36: Cash - 24-12-2025 | L36: 500000
D37: Big Tank - Extra | E37: =G37*F37 -> 570 | F37: 60 | G37: 9.5 | H37: 335 | I37: =G37*H37 -> 3182.5 | K37: Seed - 24-12-2025 | L37: 300000
D38: Small Tank - Extra | E38: =G38*F38 -> 1680 | F38: 80 | G38: 21 | H38: 290 | I38: =G38*H38 -> 6090 | K38: Surya Account - | L38: 50000
E39: =G39*F39 -> 0 | I39: =G39*H39 -> 0 | K39: Cash | L39: 136000
D40: Total: | E40: =SUM(E33:E38) -> 593783 | G40: =SUM(G33:G39) -> 8494.5 | I40: =SUM(I33:I39) -> 2530350 | K40: Total: | L40: =SUM(L33:L39) -> 2532688
D41: Number Found | E41: =CONCATENATE(ROUND((E40/E31)*100,2),"%") -> 65.98% | K41: Balance: | L41: =I40-L40 -> -2338
...

Sheet Term-11
A1: Dec2025 - Jan2026 | F1: Seed Date | G1: 46016 | I1: Profit | J1: =L2-D2 -> -469722.5
C2: Total : | D2: =SUM(D5:D30) -> 585000 | F2: Days | G2: 34 Days | K2: Total : | L2: =SUM(L5:L22) -> 115277.5
A3: Investment | F3: Growth | I3: Income
A4: # | B4: Date | C4: Item | D4: Amount | E4: Details | F4: Date | G4: Count | H4: Days | I4: # | J4: Date | K4: Item | L4: Amount | M4: Details
A5: 1 | B5: 46016 | C5: Seed | D5: 288000 | E5: from Kakinada-9L (990 ballons) | F5: 46049 | G5: 518 | H5: =IF(ISBLANK(F5),"",CONCATENATE(F5-$G$1+1," days")) -> 34 days | I5: 1 | J5: 46046 | K5: Small Tank Full | L5: 0 | M5: virus
A6: 2 | B6: 46016 | C6: Van Kiray | D6: 13000 | H6: =IF(ISBLANK(F6),"",CONCATENATE(F6-$G$1+1," days")) | I6: 2 | J6: 46049 | K6: Big Tank Full | L6: 115277.5 | M6: virus
A7: 3 | B7: 46046 | C7: Feed-2.5T | D7: 250000 | H7: =IF(ISBLANK(F7),"",CONCATENATE(F7-$G$1+1," days")) | I7: 3
A8: 4 | B8: 46046 | C8: Current bill | D8: 34000 | H8: =IF(ISBLANK(F8),"",CONCATENATE(F8-$G$1+1," days")) | I8: 4
A9: 5 | H9: =IF(ISBLANK(F9),"",CONCATENATE(F9-$G$1+1," days")) | I9: 5
A10: 6 | H10: =IF(ISBLANK(F10),"",CONCATENATE(F10-$G$1+1," days")) | I10: 6
A11: 7 | H11: =IF(ISBLANK(F11),"",CONCATENATE(F11-$G$1+1," days")) | I11: 7
A12: 8 | H12: =IF(ISBLANK(F12),"",CONCATENATE(F12-$G$1+1," days")) | I12: 8
A13: 9 | H13: =IF(ISBLANK(F13),"",CONCATENATE(F13-$G$1+1," days")) | I13: 9
A14: 10 | F14: Small Tank | I14: 10
A15: 11 | F15: Seed Date | G15: 46016 | I15: 11
A16: 12 | F16: Days | G16: 31 Days | I16: 12
A17: 13 | F17: Growth | I17: 13
A18: 14 | F18: Date | G18: Count | H18: Days | I18: 14
A19: 15 | H19: =IF(ISBLANK(F19),"",CONCATENATE(F19-$G$15+1," days")) | I19: 15
A20: 16 | H20: =IF(ISBLANK(F20),"",CONCATENATE(F20-$G$15+1," days")) | I20: 16
A21: 17 | H21: =IF(ISBLANK(F21),"",CONCATENATE(F21-$G$15+1," days")) | I21: 17
A22: 18 | H22: =IF(ISBLANK(F22),"",CONCATENATE(F22-$G$15+1," days")) | I22: 18
A23: 19 | H23: =IF(ISBLANK(F23),"",CONCATENATE(F23-$G$15+1," days")) | I23: 19
A24: 20 | H24: =IF(ISBLANK(F24),"",CONCATENATE(F24-$G$15+1," days")) | I24: 20
A25: 21 | H25: =IF(ISBLANK(F25),"",CONCATENATE(F25-$G$15+1," days")) | I25: 21
A26: 22 | I26: 22
A27: 23 | I27: 23
A28: 24 | I28: 24
A29: 25 | I29: 25
D31: Total Seed: | E31: 990000 | F31: Big Tank: | G31: 830000 | H31: Small Tank: | I31: 160000
D32: Trip | E32: Number | F32: Count | G32: Quantity | H32: Price | I32: Total | K32: Cash Credits
D33: Big Tank Full | E33: =G33*F33 -> 918673 | F33: 518 | G33: 1773.5 | H33: 65 | I33: =G33*H33 -> 115277.5 | K33: Feed | L33: 250000
E34: =G34*F34 -> 0 | I34: =G34*H34 -> 0
E35: =G35*F35 -> 0 | I35: =G35*H35 -> 0
E36: =G36*F36 -> 0 | I36: =G36*H36 -> 0
E37: =G37*F37 -> 0 | I37: =G37*H37 -> 0
E38: =G38*F38 -> 0 | I38: =G38*H38 -> 0
E39: =G39*F39 -> 0 | I39: =G39*H39 -> 0
D40: Total: | E40: =SUM(E33:E38) -> 918673 | G40: =SUM(G33:G39) -> 1773.5 | I40: =SUM(I33:I39) -> 115277.5 | K40: Total: | L40: =SUM(L33:L39) -> 250000
D41: Number Found | E41: =CONCATENATE(ROUND((E40/E31)*100,2),"%") -> 92.8% | K41: Balance: | L41: =I40-L40 -> -134722.5
...

Sheet Term-12
A1: Feb2026 - Apr2026 | F1: Seed Date | G1: 46068 | I1: Profit | J1: =L2-D2 -> -289000
C2: Total : | D2: =SUM(D5:D30) -> 289000 | F2: Days | G2: =IF(ISBLANK(G1),"",CONCATENATE(_xlfn.DAYS(TODAY(), G1-1)," Days")) -> 2 Days | K2: Total : | L2: =SUM(L5:L22) -> 0
A3: Investment | F3: Growth | I3: Income
A4: # | B4: Date | C4: Item | D4: Amount | E4: Details | F4: Date | G4: Count | H4: Days | I4: # | J4: Date | K4: Item | L4: Amount | M4: Details
A5: 1 | B5: 45703 | C5: Seed | D5: 256000 | H5: =IF(ISBLANK(F5),"",CONCATENATE(F5-$G$1+1," days")) | I5: 1
A6: 2 | B6: 45703 | C6: Van Kiray | D6: 33000 | H6: =IF(ISBLANK(F6),"",CONCATENATE(F6-$G$1+1," days")) | I6: 2
A7: 3 | H7: =IF(ISBLANK(F7),"",CONCATENATE(F7-$G$1+1," days")) | I7: 3
A8: 4 | H8: =IF(ISBLANK(F8),"",CONCATENATE(F8-$G$1+1," days")) | I8: 4
A9: 5 | H9: =IF(ISBLANK(F9),"",CONCATENATE(F9-$G$1+1," days")) | I9: 5
A10: 6 | H10: =IF(ISBLANK(F10),"",CONCATENATE(F10-$G$1+1," days")) | I10: 6
A11: 7 | H11: =IF(ISBLANK(F11),"",CONCATENATE(F11-$G$1+1," days")) | I11: 7
A12: 8 | H12: =IF(ISBLANK(F12),"",CONCATENATE(F12-$G$1+1," days")) | I12: 8
A13: 9 | H13: =IF(ISBLANK(F13),"",CONCATENATE(F13-$G$1+1," days")) | I13: 9
A14: 10 | F14: Small Tank | I14: 10
A15: 11 | F15: Seed Date | G15: 46068 | I15: 11
A16: 12 | F16: Days | G16: =IF(ISBLANK(G15),"",CONCATENATE(_xlfn.DAYS(TODAY(), G1-1)," Days")) -> 2 Days | I16: 12
A17: 13 | F17: Growth | I17: 13
A18: 14 | F18: Date | G18: Count | H18: Days | I18: 14
A19: 15 | H19: =IF(ISBLANK(F19),"",CONCATENATE(F19-$G$15+1," days")) | I19: 15
A20: 16 | H20: =IF(ISBLANK(F20),"",CONCATENATE(F20-$G$15+1," days")) | I20: 16
A21: 17 | H21: =IF(ISBLANK(F21),"",CONCATENATE(F21-$G$15+1," days")) | I21: 17
A22: 18 | H22: =IF(ISBLANK(F22),"",CONCATENATE(F22-$G$15+1," days")) | I22: 18
A23: 19 | H23: =IF(ISBLANK(F23),"",CONCATENATE(F23-$G$15+1," days")) | I23: 19
A24: 20 | H24: =IF(ISBLANK(F24),"",CONCATENATE(F24-$G$15+1," days")) | I24: 20
A25: 21 | H25: =IF(ISBLANK(F25),"",CONCATENATE(F25-$G$15+1," days")) | I25: 21
A26: 22 | I26: 22
A27: 23 | I27: 23
A28: 24 | I28: 24
A29: 25 | I29: 25
D31: Total Seed: | E31: =G31+I31 -> 800000 | F31: Big Tank: | G31: 700000 | H31: Small Tank: | I31: 100000
D32: Trip | E32: Number | F32: Count | G32: Quantity | H32: Price | I32: Total | K32: Cash Credits
E33: =G33*F33 -> 0 | I33: =G33*H33 -> 0
E34: =G34*F34 -> 0 | I34: =G34*H34 -> 0
E35: =G35*F35 -> 0 | I35: =G35*H35 -> 0
E36: =G36*F36 -> 0 | I36: =G36*H36 -> 0
E37: =G37*F37 -> 0 | I37: =G37*H37 -> 0
E38: =G38*F38 -> 0 | I38: =G38*H38 -> 0
E39: =G39*F39 -> 0 | I39: =G39*H39 -> 0
D40: Total: | E40: =SUM(E33:E38) -> 0 | G40: =SUM(G33:G39) -> 0 | I40: =SUM(I33:I39) -> 0 | K40: Total: | L40: =SUM(L33:L39) -> 0
D41: Number Found | E41: =CONCATENATE(ROUND((E40/E31)*100,2),"%") -> 0% | K41: Balance: | L41: =I40-L40 -> 0
...

Sheet Summary
A1: # | B1: Duration | C1: Term | D1: Profit | E1: Income | F1: Investment | G1: Count | H1: Days | I1: Total Duration: | N1: =DATEDIF(T1,TODAY(),"y")&" year, "&DATEDIF(T1,TODAY(),"ym")&" months, "&TODAY()-DATE(YEAR(TODAY()),MONTH(TODAY()),1)&" days" -> 2 year, 10 months, 15 days | S1: From: | T1: 45023
A2: 1 | B2: ='Term-1'!$B$1 -> May2023 - Sept2023 | C2: Term-1 | D2: =IF(F2="","",E2-F2) -> -782674 | E2: ='Term-1'!$M$2 -> 1268250 | F2: ='Term-1'!$E$2 -> 2050924 | G2: =MIN('Term-1'!H5:H11) -> 80 | H2: {='Term-1'!H2:I2} -> 75 days | I2: 0
A3: 2 | B3: ='Term-2'!$B$1 -> Sept2023 - Nov2023 | C3: Term-2 | D3: =IF(F3="","",E3-F3) -> -218110 | E3: ='Term-2'!$M$2 -> 300000 | F3: ='Term-2'!$E$2 -> 518110 | G3: =MIN('Term-2'!H5:H11) -> 325 | H3: {='Term-2'!H2:I2} -> 50 days | I3: 0
A4: 3 | B4: ='Term-3'!$B$1 -> Nov2023 - Jan2024 | C4: Term-3 | D4: =IF(F4="","",E4-F4) -> -470000 | E4: ='Term-3'!$M$2 -> 120000 | F4: ='Term-3'!$E$2 -> 590000 | G4: =MIN('Term-3'!H5:H11) -> 325 | H4: {='Term-3'!H2:I2} -> 61 days | I4: 0
A5: 4 | B5: ='Term-4'!$B$1 -> Feb2024 - May2024 | C5: Term-4 | D5: =IF(F5="","",E5-F5) -> 1098545 | E5: ='Term-4'!$M$2 -> 2700044 | F5: ='Term-4'!$E$2 -> 1601499 | G5: =MIN('Term-4'!H5:H11) -> 62 | H5: {='Term-4'!H2:I2} -> 72 Days | I5: 0
A6: 5 | B6: ='Term-5'!$B$1 -> July 2024 - Sept2024 | C6: Term-5 | D6: =IF(F6="","",E6-F6) -> 391120 | E6: ='Term-5'!$M$2 -> 1612322 | F6: ='Term-5'!$E$2 -> 1221202 | G6: =MIN('Term-5'!H5:H11) -> 110 | H6: {='Term-5'!H2:I2} -> 58 Days | I6: 0
A7: 6 | B7: ='Term-6'!$B$1 -> Sep2024 - Nov2024 | C7: Term-6 | D7: =IF(F7="","",E7-F7) -> 1002304 | E7: ='Term-6'!$M$2 -> 2415103 | F7: ='Term-6'!$E$2 -> 1412799 | G7: =MIN('Term-6'!H5:H11) -> 65 | H7: {='Term-6'!H2:I2} -> 73 Days | I7: 0
A8: 7 | B8: ='Term-7'!$B$1 -> Dec2024 - Feb2025 | C8: Term-7 | D8: =IF(F8="","",E8-F8) -> 528979 | E8: ='Term-7'!$M$2 -> 2031828 | F8: ='Term-7'!$E$2 -> 1502849 | G8: =MIN('Term-7'!H5:H11) -> 97 | H8: {='Term-7'!H2:I2} -> 79 Days | I8: 0
A9: 8 | B9: ='Term-8'!$B$1 -> Feb2025 - May2025 | C9: Term-8 | D9: =IF(F9="","",E9-F9) -> 405496 | E9: ='Term-8'!$M$2 -> 1791690 | F9: ='Term-8'!$E$2 -> 1386194 | G9: =MIN('Term-8'!H5:H11) -> 67 | H9: {='Term-8'!H2:I2} -> 78 Days | I9: 0
A10: 9 | B10: ='Term-9'!$A$1 -> July2025 - Sept2025 | C10: Term-9 | D10: =IF(F10="","",E10-F10) -> 1125929.5 | E10: ='Term-9'!$L$2 -> 2535929.5 | F10: ='Term-9'!$D$2 -> 1410000 | G10: =MIN('Term-9'!G5:G13) -> 78 | H10: {='Term-9'!G2:H2} -> 62 Days | I10: 0
A11: 10 | B11: ='Term-10'!$A$1 -> Sept2025 - Dec2025 | C11: Term-10 | D11: =IF(F11="","",E11-F11) -> 979350 | E11: ='Term-10'!$L$2 -> 2530350 | F11: ='Term-10'!$D$2 -> 1551000 | G11: =MIN('Term-10'!G5:G13) -> 58 | H11: {='Term-10'!G2:H2} -> 78 Days | I11: 0
A12: 11 | B12: ='Term-11'!$A$1 -> Dec2025 - Jan2026 | C12: Term-11 | D12: =IF(F12="","",E12-F12) -> -469722.5 | E12: ='Term-11'!$L$2 -> 115277.5 | F12: ='Term-11'!$D$2 -> 585000 | G12: =MIN('Term-11'!G5:G13) -> 518 | H12: {='Term-11'!G2:H2} -> 34 Days | I12: 0
A13: 12 | B13: ='Term-11'!$A$1 -> Dec2025 - Jan2026 | C13: Term-12 | D13: =IF(F13="","",E13-F13) -> -289000 | E13: ='Term-12'!$L$2 -> 0 | F13: ='Term-12'!$D$2 -> 289000 | G13: =MIN('Term-12'!G6:G14) -> 0 | H13: {='Term-12'!G3:H3} -> 0 | I13: 0
A14: 13
A15: 14
A16: 15
A17: 16
A18: 17
A19: 18
A20: 19
A21: 20
A22: 21
A23: 22
A24: 23
A25: Overall Total: | D25: =SUM(D2:D24) -> 3302217 | E25: =SUM(E2:E24) -> 17420794 | F25: =SUM(F2:F24) -> 14118577
B27: Profit By Year
A28: # | B28: Year | C28: Terms | D28: Profit
A29: 1 | B29: 2023 | C29: =COUNTIF(C2:C4, "*") -> 3 | D29: =SUM(D2:D4) -> -1470784
A30: 2 | B30: 2024 | C30: =COUNTIF(C4:C7, "*") -> 4 | D30: =SUM(D5:D7) -> 2491969
A31: 3 | B31: 2025 | C31: =COUNTIF(C8:C11, "*") -> 4 | D31: =SUM(D8:D11) -> 3039754.5
A32: 4 | B32: 2026 | C32: =COUNTIF(C12:C15, "*") -> 2 | D32: =SUM(D12:D15) -> -758722.5
A33: 5 | B33: 2027
A34: 6 | B34: 2028
C35: Total: | D35: =SUM(D29:D34) -> 3302217

Sheet Notes
A1: # | B1: Issue | C1: Reason | D1: Solution
A2: 1 | B2: Reason for Mortality, diseases and vibreo | C2: Ammonia,feed wastage and prawn excreta | D2: Clean land surface every 1 year
B3: White Gut | C3: Low Feed (black gut) / High Feed | D3: Serene medicine - Defender G | E3: Every week pro biatic after 40 days
B4: Number maintainance | D4: Surviwel medicine for first 3 days
B5: To increase feed | D5: Silver gold nano with probiatic for 3 days
